[2022-03-21 21:38:12,342] {taskinstance.py:1037} INFO - Dependencies all met for <TaskInstance: BQ_dag.external_task_sensor scheduled__2022-03-21T21:24:06.951066+00:00 [queued]>
[2022-03-21 21:38:12,348] {taskinstance.py:1037} INFO - Dependencies all met for <TaskInstance: BQ_dag.external_task_sensor scheduled__2022-03-21T21:24:06.951066+00:00 [queued]>
[2022-03-21 21:38:12,348] {taskinstance.py:1243} INFO - 
--------------------------------------------------------------------------------
[2022-03-21 21:38:12,348] {taskinstance.py:1244} INFO - Starting attempt 3 of 5
[2022-03-21 21:38:12,348] {taskinstance.py:1245} INFO - 
--------------------------------------------------------------------------------
[2022-03-21 21:38:12,355] {taskinstance.py:1264} INFO - Executing <Task(ExternalTaskSensor): external_task_sensor> on 2022-03-21 21:24:06.951066+00:00
[2022-03-21 21:38:12,358] {standard_task_runner.py:52} INFO - Started process 2368 to run task
[2022-03-21 21:38:12,360] {standard_task_runner.py:76} INFO - Running: ['airflow', 'tasks', 'run', 'BQ_dag', 'external_task_sensor', 'scheduled__2022-03-21T21:24:06.951066+00:00', '--job-id', '38', '--raw', '--subdir', 'DAGS_FOLDER/extract_load_dags.py', '--cfg-path', '/tmp/tmpfcfzkr9l', '--error-file', '/tmp/tmptlyp1gp1']
[2022-03-21 21:38:12,361] {standard_task_runner.py:77} INFO - Job 38: Subtask external_task_sensor
[2022-03-21 21:38:12,472] {logging_mixin.py:109} INFO - Running <TaskInstance: BQ_dag.external_task_sensor scheduled__2022-03-21T21:24:06.951066+00:00 [running]> on host 7fae4c5ec6da
[2022-03-21 21:38:12,514] {taskinstance.py:1429} INFO - Exporting the following env vars:
AIRFLOW_CTX_DAG_OWNER=airflow
AIRFLOW_CTX_DAG_ID=BQ_dag
AIRFLOW_CTX_TASK_ID=external_task_sensor
AIRFLOW_CTX_EXECUTION_DATE=2022-03-21T21:24:06.951066+00:00
AIRFLOW_CTX_DAG_RUN_ID=scheduled__2022-03-21T21:24:06.951066+00:00
[2022-03-21 21:38:12,514] {external_task.py:169} INFO - Poking for tasks ['remove_dataset_task'] in dag EL_dag on 2022-03-21T21:24:06.951066+00:00 ... 
[2022-03-21 21:39:12,528] {external_task.py:169} INFO - Poking for tasks ['remove_dataset_task'] in dag EL_dag on 2022-03-21T21:24:06.951066+00:00 ... 
[2022-03-21 21:39:53,592] {local_task_job.py:211} WARNING - State of this instance has been externally set to restarting. Terminating instance.
[2022-03-21 21:39:53,593] {process_utils.py:120} INFO - Sending Signals.SIGTERM to group 2368. PIDs of all processes in the group: [2368]
[2022-03-21 21:39:53,593] {process_utils.py:75} INFO - Sending the signal Signals.SIGTERM to group 2368
[2022-03-21 21:39:53,593] {taskinstance.py:1413} ERROR - Received SIGTERM. Terminating subprocesses.
[2022-03-21 21:39:53,605] {taskinstance.py:1718} ERROR - Task failed with exception
Traceback (most recent call last):
  File "/usr/local/lib/python3.9/site-packages/airflow/models/taskinstance.py", line 1334, in _run_raw_task
    self._execute_task_with_callbacks(context)
  File "/usr/local/lib/python3.9/site-packages/airflow/models/taskinstance.py", line 1460, in _execute_task_with_callbacks
    result = self._execute_task(context, self.task)
  File "/usr/local/lib/python3.9/site-packages/airflow/models/taskinstance.py", line 1516, in _execute_task
    result = execute_callable(context=context)
  File "/usr/local/lib/python3.9/site-packages/airflow/sensors/base.py", line 249, in execute
    time.sleep(self._get_next_poke_interval(started_at, run_duration, try_number))
  File "/usr/local/lib/python3.9/site-packages/airflow/models/taskinstance.py", line 1415, in signal_handler
    raise AirflowException("Task received SIGTERM signal")
airflow.exceptions.AirflowException: Task received SIGTERM signal
[2022-03-21 21:39:53,608] {taskinstance.py:1272} INFO - Marking task as UP_FOR_RETRY. dag_id=BQ_dag, task_id=external_task_sensor, execution_date=20220321T212406, start_date=20220321T213812, end_date=20220321T213953
[2022-03-21 21:39:53,619] {standard_task_runner.py:89} ERROR - Failed to execute job 38 for task external_task_sensor
Traceback (most recent call last):
  File "/usr/local/lib/python3.9/site-packages/airflow/task/task_runner/standard_task_runner.py", line 85, in _start_by_fork
    args.func(args, dag=self.dag)
  File "/usr/local/lib/python3.9/site-packages/airflow/cli/cli_parser.py", line 48, in command
    return func(*args, **kwargs)
  File "/usr/local/lib/python3.9/site-packages/airflow/utils/cli.py", line 92, in wrapper
    return f(*args, **kwargs)
  File "/usr/local/lib/python3.9/site-packages/airflow/cli/commands/task_command.py", line 298, in task_run
    _run_task_by_selected_method(args, dag, ti)
  File "/usr/local/lib/python3.9/site-packages/airflow/cli/commands/task_command.py", line 107, in _run_task_by_selected_method
    _run_raw_task(args, ti)
  File "/usr/local/lib/python3.9/site-packages/airflow/cli/commands/task_command.py", line 180, in _run_raw_task
    ti._run_raw_task(
  File "/usr/local/lib/python3.9/site-packages/airflow/utils/session.py", line 70, in wrapper
    return func(*args, session=session, **kwargs)
  File "/usr/local/lib/python3.9/site-packages/airflow/models/taskinstance.py", line 1334, in _run_raw_task
    self._execute_task_with_callbacks(context)
  File "/usr/local/lib/python3.9/site-packages/airflow/models/taskinstance.py", line 1460, in _execute_task_with_callbacks
    result = self._execute_task(context, self.task)
  File "/usr/local/lib/python3.9/site-packages/airflow/models/taskinstance.py", line 1516, in _execute_task
    result = execute_callable(context=context)
  File "/usr/local/lib/python3.9/site-packages/airflow/sensors/base.py", line 249, in execute
    time.sleep(self._get_next_poke_interval(started_at, run_duration, try_number))
  File "/usr/local/lib/python3.9/site-packages/airflow/models/taskinstance.py", line 1415, in signal_handler
    raise AirflowException("Task received SIGTERM signal")
airflow.exceptions.AirflowException: Task received SIGTERM signal
[2022-03-21 21:39:53,646] {process_utils.py:70} INFO - Process psutil.Process(pid=2368, status='terminated', exitcode=1, started='21:38:11') (2368) terminated with exit code 1
