[2022-03-24 15:42:30,792] {taskinstance.py:1037} INFO - Dependencies all met for <TaskInstance: dbt_dag.model.iowa.monthly_vendor_revenue manual__2022-03-23T19:14:12.667416+00:00 [queued]>
[2022-03-24 15:42:30,801] {taskinstance.py:1037} INFO - Dependencies all met for <TaskInstance: dbt_dag.model.iowa.monthly_vendor_revenue manual__2022-03-23T19:14:12.667416+00:00 [queued]>
[2022-03-24 15:42:30,801] {taskinstance.py:1243} INFO - 
--------------------------------------------------------------------------------
[2022-03-24 15:42:30,801] {taskinstance.py:1244} INFO - Starting attempt 1 of 1
[2022-03-24 15:42:30,801] {taskinstance.py:1245} INFO - 
--------------------------------------------------------------------------------
[2022-03-24 15:42:30,810] {taskinstance.py:1264} INFO - Executing <Task(BashOperator): model.iowa.monthly_vendor_revenue> on 2022-03-23 19:14:12.667416+00:00
[2022-03-24 15:42:30,812] {standard_task_runner.py:52} INFO - Started process 498 to run task
[2022-03-24 15:42:30,815] {standard_task_runner.py:76} INFO - Running: ['airflow', 'tasks', 'run', 'dbt_dag', 'model.iowa.monthly_vendor_revenue', 'manual__2022-03-23T19:14:12.667416+00:00', '--job-id', '181', '--raw', '--subdir', 'DAGS_FOLDER/transform_dags.py', '--cfg-path', '/tmp/tmp1tlz4h_o', '--error-file', '/tmp/tmphb04dydu']
[2022-03-24 15:42:30,815] {standard_task_runner.py:77} INFO - Job 181: Subtask model.iowa.monthly_vendor_revenue
[2022-03-24 15:42:30,864] {logging_mixin.py:109} INFO - Running <TaskInstance: dbt_dag.model.iowa.monthly_vendor_revenue manual__2022-03-23T19:14:12.667416+00:00 [running]> on host a91ac75a8f43
[2022-03-24 15:42:30,909] {taskinstance.py:1429} INFO - Exporting the following env vars:
AIRFLOW_CTX_DAG_OWNER=airflow
AIRFLOW_CTX_DAG_ID=dbt_dag
AIRFLOW_CTX_TASK_ID=model.iowa.monthly_vendor_revenue
AIRFLOW_CTX_EXECUTION_DATE=2022-03-23T19:14:12.667416+00:00
AIRFLOW_CTX_DAG_RUN_ID=manual__2022-03-23T19:14:12.667416+00:00
[2022-03-24 15:42:30,909] {subprocess.py:62} INFO - Tmp dir root location: 
 /tmp
[2022-03-24 15:42:30,910] {subprocess.py:74} INFO - Running command: ['bash', '-c', '\n            cd /opt/iowa/dbt/iowa &&\n            dbt --no-write-json run --target dev --models monthly_vendor_revenue\n            ']
[2022-03-24 15:42:30,914] {subprocess.py:85} INFO - Output:
[2022-03-24 15:42:33,870] {subprocess.py:89} INFO - 15:42:33  Running with dbt=1.0.4
[2022-03-24 15:42:33,919] {subprocess.py:89} INFO - 15:42:33  Found 8 models, 2 tests, 0 snapshots, 0 analyses, 188 macros, 0 operations, 0 seed files, 1 source, 0 exposures, 0 metrics
[2022-03-24 15:42:33,920] {subprocess.py:89} INFO - 15:42:33
[2022-03-24 15:42:43,113] {subprocess.py:89} INFO - 15:42:43  Concurrency: 4 threads (target='dev')
[2022-03-24 15:42:43,113] {subprocess.py:89} INFO - 15:42:43
[2022-03-24 15:42:43,117] {subprocess.py:89} INFO - 15:42:43  1 of 1 START incremental model iowa_staging.monthly_vendor_revenue.............. [RUN]
[2022-03-24 15:42:48,569] {subprocess.py:89} INFO - 15:42:48  1 of 1 ERROR creating incremental model iowa_staging.monthly_vendor_revenue..... [ERROR in 5.45s]
[2022-03-24 15:42:48,571] {subprocess.py:89} INFO - 15:42:48
[2022-03-24 15:42:48,571] {subprocess.py:89} INFO - 15:42:48  Finished running 1 incremental model in 14.65s.
[2022-03-24 15:42:48,572] {subprocess.py:89} INFO - 15:42:48
[2022-03-24 15:42:48,573] {subprocess.py:89} INFO - 15:42:48  Completed with 1 error and 0 warnings:
[2022-03-24 15:42:48,573] {subprocess.py:89} INFO - 15:42:48
[2022-03-24 15:42:48,573] {subprocess.py:89} INFO - 15:42:48  Database Error in model monthly_vendor_revenue (models/marts/sales/monthly_vendor_revenue.sql)
[2022-03-24 15:42:48,574] {subprocess.py:89} INFO - 15:42:48    Syntax error: Expected ")" but got ";" at [20:17]
[2022-03-24 15:42:48,574] {subprocess.py:89} INFO - 15:42:48    compiled SQL at target/run/iowa/models/marts/sales/monthly_vendor_revenue.sql
[2022-03-24 15:42:48,574] {subprocess.py:89} INFO - 15:42:48
[2022-03-24 15:42:48,574] {subprocess.py:89} INFO - 15:42:48  Done. PASS=0 WARN=0 ERROR=1 SKIP=0 TOTAL=1
[2022-03-24 15:42:52,016] {subprocess.py:93} INFO - Command exited with return code 1
[2022-03-24 15:42:52,031] {taskinstance.py:1718} ERROR - Task failed with exception
Traceback (most recent call last):
  File "/usr/local/lib/python3.9/site-packages/airflow/models/taskinstance.py", line 1334, in _run_raw_task
    self._execute_task_with_callbacks(context)
  File "/usr/local/lib/python3.9/site-packages/airflow/models/taskinstance.py", line 1460, in _execute_task_with_callbacks
    result = self._execute_task(context, self.task)
  File "/usr/local/lib/python3.9/site-packages/airflow/models/taskinstance.py", line 1516, in _execute_task
    result = execute_callable(context=context)
  File "/usr/local/lib/python3.9/site-packages/airflow/operators/bash.py", line 187, in execute
    raise AirflowException(
airflow.exceptions.AirflowException: Bash command failed. The command returned a non-zero exit code 1.
[2022-03-24 15:42:52,037] {taskinstance.py:1272} INFO - Marking task as FAILED. dag_id=dbt_dag, task_id=model.iowa.monthly_vendor_revenue, execution_date=20220323T191412, start_date=20220324T154230, end_date=20220324T154252
[2022-03-24 15:42:52,047] {standard_task_runner.py:89} ERROR - Failed to execute job 181 for task model.iowa.monthly_vendor_revenue
Traceback (most recent call last):
  File "/usr/local/lib/python3.9/site-packages/airflow/task/task_runner/standard_task_runner.py", line 85, in _start_by_fork
    args.func(args, dag=self.dag)
  File "/usr/local/lib/python3.9/site-packages/airflow/cli/cli_parser.py", line 48, in command
    return func(*args, **kwargs)
  File "/usr/local/lib/python3.9/site-packages/airflow/utils/cli.py", line 92, in wrapper
    return f(*args, **kwargs)
  File "/usr/local/lib/python3.9/site-packages/airflow/cli/commands/task_command.py", line 298, in task_run
    _run_task_by_selected_method(args, dag, ti)
  File "/usr/local/lib/python3.9/site-packages/airflow/cli/commands/task_command.py", line 107, in _run_task_by_selected_method
    _run_raw_task(args, ti)
  File "/usr/local/lib/python3.9/site-packages/airflow/cli/commands/task_command.py", line 180, in _run_raw_task
    ti._run_raw_task(
  File "/usr/local/lib/python3.9/site-packages/airflow/utils/session.py", line 70, in wrapper
    return func(*args, session=session, **kwargs)
  File "/usr/local/lib/python3.9/site-packages/airflow/models/taskinstance.py", line 1334, in _run_raw_task
    self._execute_task_with_callbacks(context)
  File "/usr/local/lib/python3.9/site-packages/airflow/models/taskinstance.py", line 1460, in _execute_task_with_callbacks
    result = self._execute_task(context, self.task)
  File "/usr/local/lib/python3.9/site-packages/airflow/models/taskinstance.py", line 1516, in _execute_task
    result = execute_callable(context=context)
  File "/usr/local/lib/python3.9/site-packages/airflow/operators/bash.py", line 187, in execute
    raise AirflowException(
airflow.exceptions.AirflowException: Bash command failed. The command returned a non-zero exit code 1.
[2022-03-24 15:42:52,061] {local_task_job.py:154} INFO - Task exited with return code 1
[2022-03-24 15:42:52,093] {local_task_job.py:264} INFO - 0 downstream tasks scheduled from follow-on schedule check
