[2022-03-21 21:30:38,531] {taskinstance.py:1037} INFO - Dependencies all met for <TaskInstance: EL_dag.extract_task scheduled__2012-02-02T01:00:00+00:00 [queued]>
[2022-03-21 21:30:38,538] {taskinstance.py:1037} INFO - Dependencies all met for <TaskInstance: EL_dag.extract_task scheduled__2012-02-02T01:00:00+00:00 [queued]>
[2022-03-21 21:30:38,538] {taskinstance.py:1243} INFO - 
--------------------------------------------------------------------------------
[2022-03-21 21:30:38,538] {taskinstance.py:1244} INFO - Starting attempt 3 of 4
[2022-03-21 21:30:38,538] {taskinstance.py:1245} INFO - 
--------------------------------------------------------------------------------
[2022-03-21 21:30:38,548] {taskinstance.py:1264} INFO - Executing <Task(PythonOperator): extract_task> on 2012-02-02 01:00:00+00:00
[2022-03-21 21:30:38,552] {standard_task_runner.py:52} INFO - Started process 1851 to run task
[2022-03-21 21:30:38,555] {standard_task_runner.py:76} INFO - Running: ['airflow', 'tasks', 'run', 'EL_dag', 'extract_task', 'scheduled__2012-02-02T01:00:00+00:00', '--job-id', '26', '--raw', '--subdir', 'DAGS_FOLDER/extract_load_dags.py', '--cfg-path', '/tmp/tmpk4xm03ge', '--error-file', '/tmp/tmp03uh99a7']
[2022-03-21 21:30:38,555] {standard_task_runner.py:77} INFO - Job 26: Subtask extract_task
[2022-03-21 21:30:38,678] {logging_mixin.py:109} INFO - Running <TaskInstance: EL_dag.extract_task scheduled__2012-02-02T01:00:00+00:00 [running]> on host 7fae4c5ec6da
[2022-03-21 21:30:38,703] {logging_mixin.py:109} WARNING - /usr/local/lib/python3.9/site-packages/airflow/utils/context.py:156 AirflowContextDeprecationWarning: Accessing 'execution_date' from the template is deprecated and will be removed in a future version. Please use 'data_interval_start' or 'logical_date' instead.
[2022-03-21 21:30:38,722] {taskinstance.py:1429} INFO - Exporting the following env vars:
AIRFLOW_CTX_DAG_OWNER=airflow
AIRFLOW_CTX_DAG_ID=EL_dag
AIRFLOW_CTX_TASK_ID=extract_task
AIRFLOW_CTX_EXECUTION_DATE=2012-02-02T01:00:00+00:00
AIRFLOW_CTX_DAG_RUN_ID=scheduled__2012-02-02T01:00:00+00:00
[2022-03-21 21:30:38,723] {logging_mixin.py:109} INFO - 02 2012
[2022-03-21 21:30:43,173] {logging_mixin.py:109} INFO - the response is  200
[2022-03-21 21:30:43,173] {logging_mixin.py:109} INFO - here.........
[2022-03-21 21:30:43,208] {logging_mixin.py:109} INFO -   invoice_line_no                     date  ... sale_liters sale_gallons
0    S04075500017  2012-02-14T00:00:00.000  ...        1.50         0.40
1    S03884100012  2012-02-02T00:00:00.000  ...       10.50         2.77
2    S04290800042  2012-02-28T00:00:00.000  ...        3.00         0.79
3    S04239500044  2012-02-23T00:00:00.000  ...        9.00         2.38
4    S04130800083  2012-02-16T00:00:00.000  ...       10.50         2.77

[5 rows x 24 columns]
[2022-03-21 21:30:43,222] {taskinstance.py:1718} ERROR - Task failed with exception
Traceback (most recent call last):
  File "/usr/local/lib/python3.9/site-packages/airflow/models/taskinstance.py", line 1334, in _run_raw_task
    self._execute_task_with_callbacks(context)
  File "/usr/local/lib/python3.9/site-packages/airflow/models/taskinstance.py", line 1460, in _execute_task_with_callbacks
    result = self._execute_task(context, self.task)
  File "/usr/local/lib/python3.9/site-packages/airflow/models/taskinstance.py", line 1516, in _execute_task
    result = execute_callable(context=context)
  File "/usr/local/lib/python3.9/site-packages/airflow/operators/python.py", line 174, in execute
    return_value = self.execute_callable()
  File "/usr/local/lib/python3.9/site-packages/airflow/operators/python.py", line 188, in execute_callable
    return self.python_callable(*self.op_args, **self.op_kwargs)
  File "/opt/iowa/airflow/dags/extract_load.py", line 28, in get_api_data
    df.to_parquet(f"../data/data_{year}-{month}.parquet",index=False)
  File "/usr/local/lib/python3.9/site-packages/pandas/util/_decorators.py", line 207, in wrapper
    return func(*args, **kwargs)
  File "/usr/local/lib/python3.9/site-packages/pandas/core/frame.py", line 2677, in to_parquet
    return to_parquet(
  File "/usr/local/lib/python3.9/site-packages/pandas/io/parquet.py", line 416, in to_parquet
    impl.write(
  File "/usr/local/lib/python3.9/site-packages/pandas/io/parquet.py", line 175, in write
    path_or_handle, handles, kwargs["filesystem"] = _get_path_or_handle(
  File "/usr/local/lib/python3.9/site-packages/pandas/io/parquet.py", line 101, in _get_path_or_handle
    handles = get_handle(
  File "/usr/local/lib/python3.9/site-packages/pandas/io/common.py", line 711, in get_handle
    handle = open(handle, ioargs.mode)
FileNotFoundError: [Errno 2] No such file or directory: '../data/data_2012-02.parquet'
[2022-03-21 21:30:43,242] {taskinstance.py:1272} INFO - Marking task as UP_FOR_RETRY. dag_id=EL_dag, task_id=extract_task, execution_date=20120202T010000, start_date=20220321T213038, end_date=20220321T213043
[2022-03-21 21:30:43,255] {standard_task_runner.py:89} ERROR - Failed to execute job 26 for task extract_task
Traceback (most recent call last):
  File "/usr/local/lib/python3.9/site-packages/airflow/task/task_runner/standard_task_runner.py", line 85, in _start_by_fork
    args.func(args, dag=self.dag)
  File "/usr/local/lib/python3.9/site-packages/airflow/cli/cli_parser.py", line 48, in command
    return func(*args, **kwargs)
  File "/usr/local/lib/python3.9/site-packages/airflow/utils/cli.py", line 92, in wrapper
    return f(*args, **kwargs)
  File "/usr/local/lib/python3.9/site-packages/airflow/cli/commands/task_command.py", line 298, in task_run
    _run_task_by_selected_method(args, dag, ti)
  File "/usr/local/lib/python3.9/site-packages/airflow/cli/commands/task_command.py", line 107, in _run_task_by_selected_method
    _run_raw_task(args, ti)
  File "/usr/local/lib/python3.9/site-packages/airflow/cli/commands/task_command.py", line 180, in _run_raw_task
    ti._run_raw_task(
  File "/usr/local/lib/python3.9/site-packages/airflow/utils/session.py", line 70, in wrapper
    return func(*args, session=session, **kwargs)
  File "/usr/local/lib/python3.9/site-packages/airflow/models/taskinstance.py", line 1334, in _run_raw_task
    self._execute_task_with_callbacks(context)
  File "/usr/local/lib/python3.9/site-packages/airflow/models/taskinstance.py", line 1460, in _execute_task_with_callbacks
    result = self._execute_task(context, self.task)
  File "/usr/local/lib/python3.9/site-packages/airflow/models/taskinstance.py", line 1516, in _execute_task
    result = execute_callable(context=context)
  File "/usr/local/lib/python3.9/site-packages/airflow/operators/python.py", line 174, in execute
    return_value = self.execute_callable()
  File "/usr/local/lib/python3.9/site-packages/airflow/operators/python.py", line 188, in execute_callable
    return self.python_callable(*self.op_args, **self.op_kwargs)
  File "/opt/iowa/airflow/dags/extract_load.py", line 28, in get_api_data
    df.to_parquet(f"../data/data_{year}-{month}.parquet",index=False)
  File "/usr/local/lib/python3.9/site-packages/pandas/util/_decorators.py", line 207, in wrapper
    return func(*args, **kwargs)
  File "/usr/local/lib/python3.9/site-packages/pandas/core/frame.py", line 2677, in to_parquet
    return to_parquet(
  File "/usr/local/lib/python3.9/site-packages/pandas/io/parquet.py", line 416, in to_parquet
    impl.write(
  File "/usr/local/lib/python3.9/site-packages/pandas/io/parquet.py", line 175, in write
    path_or_handle, handles, kwargs["filesystem"] = _get_path_or_handle(
  File "/usr/local/lib/python3.9/site-packages/pandas/io/parquet.py", line 101, in _get_path_or_handle
    handles = get_handle(
  File "/usr/local/lib/python3.9/site-packages/pandas/io/common.py", line 711, in get_handle
    handle = open(handle, ioargs.mode)
FileNotFoundError: [Errno 2] No such file or directory: '../data/data_2012-02.parquet'
[2022-03-21 21:30:43,264] {local_task_job.py:154} INFO - Task exited with return code 1
[2022-03-21 21:30:43,374] {local_task_job.py:264} INFO - 0 downstream tasks scheduled from follow-on schedule check
