[2022-03-24 14:38:35,776] {taskinstance.py:1037} INFO - Dependencies all met for <TaskInstance: dbt_dag.model.iowa.general_county_facts manual__2022-03-23T19:14:12.667416+00:00 [queued]>
[2022-03-24 14:38:35,783] {taskinstance.py:1037} INFO - Dependencies all met for <TaskInstance: dbt_dag.model.iowa.general_county_facts manual__2022-03-23T19:14:12.667416+00:00 [queued]>
[2022-03-24 14:38:35,784] {taskinstance.py:1243} INFO - 
--------------------------------------------------------------------------------
[2022-03-24 14:38:35,784] {taskinstance.py:1244} INFO - Starting attempt 5 of 5
[2022-03-24 14:38:35,784] {taskinstance.py:1245} INFO - 
--------------------------------------------------------------------------------
[2022-03-24 14:38:35,792] {taskinstance.py:1264} INFO - Executing <Task(BashOperator): model.iowa.general_county_facts> on 2022-03-23 19:14:12.667416+00:00
[2022-03-24 14:38:35,794] {standard_task_runner.py:52} INFO - Started process 1180 to run task
[2022-03-24 14:38:35,796] {standard_task_runner.py:76} INFO - Running: ['airflow', 'tasks', 'run', 'dbt_dag', 'model.iowa.general_county_facts', 'manual__2022-03-23T19:14:12.667416+00:00', '--job-id', '160', '--raw', '--subdir', 'DAGS_FOLDER/transform_dags.py', '--cfg-path', '/tmp/tmpyqzj7mlj', '--error-file', '/tmp/tmpq1dyce45']
[2022-03-24 14:38:35,797] {standard_task_runner.py:77} INFO - Job 160: Subtask model.iowa.general_county_facts
[2022-03-24 14:38:35,850] {logging_mixin.py:109} INFO - Running <TaskInstance: dbt_dag.model.iowa.general_county_facts manual__2022-03-23T19:14:12.667416+00:00 [running]> on host a91ac75a8f43
[2022-03-24 14:38:35,900] {taskinstance.py:1429} INFO - Exporting the following env vars:
AIRFLOW_CTX_DAG_OWNER=airflow
AIRFLOW_CTX_DAG_ID=dbt_dag
AIRFLOW_CTX_TASK_ID=model.iowa.general_county_facts
AIRFLOW_CTX_EXECUTION_DATE=2022-03-23T19:14:12.667416+00:00
AIRFLOW_CTX_DAG_RUN_ID=manual__2022-03-23T19:14:12.667416+00:00
[2022-03-24 14:38:35,900] {subprocess.py:62} INFO - Tmp dir root location: 
 /tmp
[2022-03-24 14:38:35,901] {subprocess.py:74} INFO - Running command: ['bash', '-c', '\n            cd /opt/iowa/dbt/iowa &&\n            dbt --no-write-json run --target dev --models general_county_facts\n            ']
[2022-03-24 14:38:35,905] {subprocess.py:85} INFO - Output:
[2022-03-24 14:38:40,117] {subprocess.py:89} INFO - 14:38:40  Running with dbt=1.0.4
[2022-03-24 14:38:40,248] {subprocess.py:89} INFO - 14:38:40  Found 5 models, 2 tests, 0 snapshots, 0 analyses, 188 macros, 0 operations, 0 seed files, 1 source, 0 exposures, 0 metrics
[2022-03-24 14:38:40,251] {subprocess.py:89} INFO - 14:38:40
[2022-03-24 14:38:48,036] {subprocess.py:89} INFO - 14:38:48  Concurrency: 4 threads (target='dev')
[2022-03-24 14:38:48,037] {subprocess.py:89} INFO - 14:38:48
[2022-03-24 14:38:48,042] {subprocess.py:89} INFO - 14:38:48  1 of 1 START incremental model iowa_staging.general_county_facts................ [RUN]
[2022-03-24 14:38:54,675] {subprocess.py:89} INFO - 14:38:54  1 of 1 ERROR creating incremental model iowa_staging.general_county_facts....... [ERROR in 6.63s]
[2022-03-24 14:38:54,677] {subprocess.py:89} INFO - 14:38:54
[2022-03-24 14:38:54,677] {subprocess.py:89} INFO - 14:38:54  Finished running 1 incremental model in 14.43s.
[2022-03-24 14:38:54,677] {subprocess.py:89} INFO - 14:38:54
[2022-03-24 14:38:54,678] {subprocess.py:89} INFO - 14:38:54  Completed with 1 error and 0 warnings:
[2022-03-24 14:38:54,678] {subprocess.py:89} INFO - 14:38:54
[2022-03-24 14:38:54,679] {subprocess.py:89} INFO - 14:38:54  Database Error in model general_county_facts (models/marts/sales/general_county_facts.sql)
[2022-03-24 14:38:54,679] {subprocess.py:89} INFO - 14:38:54    Name store not found inside DBT_INTERNAL_SOURCE at [46:145]
[2022-03-24 14:38:54,679] {subprocess.py:89} INFO - 14:38:54    compiled SQL at target/run/iowa/models/marts/sales/general_county_facts.sql
[2022-03-24 14:38:54,680] {subprocess.py:89} INFO - 14:38:54
[2022-03-24 14:38:54,680] {subprocess.py:89} INFO - 14:38:54  Done. PASS=0 WARN=0 ERROR=1 SKIP=0 TOTAL=1
[2022-03-24 14:38:55,961] {subprocess.py:93} INFO - Command exited with return code 1
[2022-03-24 14:38:55,973] {taskinstance.py:1718} ERROR - Task failed with exception
Traceback (most recent call last):
  File "/usr/local/lib/python3.9/site-packages/airflow/models/taskinstance.py", line 1334, in _run_raw_task
    self._execute_task_with_callbacks(context)
  File "/usr/local/lib/python3.9/site-packages/airflow/models/taskinstance.py", line 1460, in _execute_task_with_callbacks
    result = self._execute_task(context, self.task)
  File "/usr/local/lib/python3.9/site-packages/airflow/models/taskinstance.py", line 1516, in _execute_task
    result = execute_callable(context=context)
  File "/usr/local/lib/python3.9/site-packages/airflow/operators/bash.py", line 187, in execute
    raise AirflowException(
airflow.exceptions.AirflowException: Bash command failed. The command returned a non-zero exit code 1.
[2022-03-24 14:38:55,978] {taskinstance.py:1272} INFO - Marking task as FAILED. dag_id=dbt_dag, task_id=model.iowa.general_county_facts, execution_date=20220323T191412, start_date=20220324T143835, end_date=20220324T143855
[2022-03-24 14:38:55,987] {standard_task_runner.py:89} ERROR - Failed to execute job 160 for task model.iowa.general_county_facts
Traceback (most recent call last):
  File "/usr/local/lib/python3.9/site-packages/airflow/task/task_runner/standard_task_runner.py", line 85, in _start_by_fork
    args.func(args, dag=self.dag)
  File "/usr/local/lib/python3.9/site-packages/airflow/cli/cli_parser.py", line 48, in command
    return func(*args, **kwargs)
  File "/usr/local/lib/python3.9/site-packages/airflow/utils/cli.py", line 92, in wrapper
    return f(*args, **kwargs)
  File "/usr/local/lib/python3.9/site-packages/airflow/cli/commands/task_command.py", line 298, in task_run
    _run_task_by_selected_method(args, dag, ti)
  File "/usr/local/lib/python3.9/site-packages/airflow/cli/commands/task_command.py", line 107, in _run_task_by_selected_method
    _run_raw_task(args, ti)
  File "/usr/local/lib/python3.9/site-packages/airflow/cli/commands/task_command.py", line 180, in _run_raw_task
    ti._run_raw_task(
  File "/usr/local/lib/python3.9/site-packages/airflow/utils/session.py", line 70, in wrapper
    return func(*args, session=session, **kwargs)
  File "/usr/local/lib/python3.9/site-packages/airflow/models/taskinstance.py", line 1334, in _run_raw_task
    self._execute_task_with_callbacks(context)
  File "/usr/local/lib/python3.9/site-packages/airflow/models/taskinstance.py", line 1460, in _execute_task_with_callbacks
    result = self._execute_task(context, self.task)
  File "/usr/local/lib/python3.9/site-packages/airflow/models/taskinstance.py", line 1516, in _execute_task
    result = execute_callable(context=context)
  File "/usr/local/lib/python3.9/site-packages/airflow/operators/bash.py", line 187, in execute
    raise AirflowException(
airflow.exceptions.AirflowException: Bash command failed. The command returned a non-zero exit code 1.
[2022-03-24 14:38:56,010] {local_task_job.py:154} INFO - Task exited with return code 1
[2022-03-24 14:38:56,040] {local_task_job.py:264} INFO - 0 downstream tasks scheduled from follow-on schedule check
