[2022-03-24 14:36:23,014] {taskinstance.py:1037} INFO - Dependencies all met for <TaskInstance: dbt_dag.model.iowa.staging_sales manual__2022-03-23T19:14:12.667416+00:00 [queued]>
[2022-03-24 14:36:23,020] {taskinstance.py:1037} INFO - Dependencies all met for <TaskInstance: dbt_dag.model.iowa.staging_sales manual__2022-03-23T19:14:12.667416+00:00 [queued]>
[2022-03-24 14:36:23,020] {taskinstance.py:1243} INFO - 
--------------------------------------------------------------------------------
[2022-03-24 14:36:23,020] {taskinstance.py:1244} INFO - Starting attempt 13 of 13
[2022-03-24 14:36:23,021] {taskinstance.py:1245} INFO - 
--------------------------------------------------------------------------------
[2022-03-24 14:36:23,029] {taskinstance.py:1264} INFO - Executing <Task(BashOperator): model.iowa.staging_sales> on 2022-03-23 19:14:12.667416+00:00
[2022-03-24 14:36:23,030] {standard_task_runner.py:52} INFO - Started process 1020 to run task
[2022-03-24 14:36:23,032] {standard_task_runner.py:76} INFO - Running: ['airflow', 'tasks', 'run', 'dbt_dag', 'model.iowa.staging_sales', 'manual__2022-03-23T19:14:12.667416+00:00', '--job-id', '157', '--raw', '--subdir', 'DAGS_FOLDER/transform_dags.py', '--cfg-path', '/tmp/tmpnqpnttpg', '--error-file', '/tmp/tmpe7hk5xam']
[2022-03-24 14:36:23,033] {standard_task_runner.py:77} INFO - Job 157: Subtask model.iowa.staging_sales
[2022-03-24 14:36:23,078] {logging_mixin.py:109} INFO - Running <TaskInstance: dbt_dag.model.iowa.staging_sales manual__2022-03-23T19:14:12.667416+00:00 [running]> on host a91ac75a8f43
[2022-03-24 14:36:23,120] {taskinstance.py:1429} INFO - Exporting the following env vars:
AIRFLOW_CTX_DAG_OWNER=airflow
AIRFLOW_CTX_DAG_ID=dbt_dag
AIRFLOW_CTX_TASK_ID=model.iowa.staging_sales
AIRFLOW_CTX_EXECUTION_DATE=2022-03-23T19:14:12.667416+00:00
AIRFLOW_CTX_DAG_RUN_ID=manual__2022-03-23T19:14:12.667416+00:00
[2022-03-24 14:36:23,120] {subprocess.py:62} INFO - Tmp dir root location: 
 /tmp
[2022-03-24 14:36:23,120] {subprocess.py:74} INFO - Running command: ['bash', '-c', '\n            cd /opt/iowa/dbt/iowa &&\n            dbt --no-write-json run --target dev --models staging_sales\n            ']
[2022-03-24 14:36:23,124] {subprocess.py:85} INFO - Output:
[2022-03-24 14:36:25,709] {subprocess.py:89} INFO - 14:36:25  Running with dbt=1.0.4
[2022-03-24 14:36:27,670] {subprocess.py:89} INFO - 14:36:27  Encountered an error:
[2022-03-24 14:36:27,670] {subprocess.py:89} INFO - Parsing Error
[2022-03-24 14:36:27,670] {subprocess.py:89} INFO -   Invalid test config given in models/marts/sales/schema.yml:
[2022-03-24 14:36:27,670] {subprocess.py:89} INFO -   	test definition dictionary must have exactly one key, got [('not_null', None), ('severity', 'error')] instead (2 keys)
[2022-03-24 14:36:27,670] {subprocess.py:89} INFO -   	@: UnparsedNodeUpdate(original_file_path='model...ne)
[2022-03-24 14:36:27,834] {subprocess.py:93} INFO - Command exited with return code 2
[2022-03-24 14:36:27,846] {taskinstance.py:1718} ERROR - Task failed with exception
Traceback (most recent call last):
  File "/usr/local/lib/python3.9/site-packages/airflow/models/taskinstance.py", line 1334, in _run_raw_task
    self._execute_task_with_callbacks(context)
  File "/usr/local/lib/python3.9/site-packages/airflow/models/taskinstance.py", line 1460, in _execute_task_with_callbacks
    result = self._execute_task(context, self.task)
  File "/usr/local/lib/python3.9/site-packages/airflow/models/taskinstance.py", line 1516, in _execute_task
    result = execute_callable(context=context)
  File "/usr/local/lib/python3.9/site-packages/airflow/operators/bash.py", line 187, in execute
    raise AirflowException(
airflow.exceptions.AirflowException: Bash command failed. The command returned a non-zero exit code 2.
[2022-03-24 14:36:27,850] {taskinstance.py:1272} INFO - Marking task as FAILED. dag_id=dbt_dag, task_id=model.iowa.staging_sales, execution_date=20220323T191412, start_date=20220324T143623, end_date=20220324T143627
[2022-03-24 14:36:27,860] {standard_task_runner.py:89} ERROR - Failed to execute job 157 for task model.iowa.staging_sales
Traceback (most recent call last):
  File "/usr/local/lib/python3.9/site-packages/airflow/task/task_runner/standard_task_runner.py", line 85, in _start_by_fork
    args.func(args, dag=self.dag)
  File "/usr/local/lib/python3.9/site-packages/airflow/cli/cli_parser.py", line 48, in command
    return func(*args, **kwargs)
  File "/usr/local/lib/python3.9/site-packages/airflow/utils/cli.py", line 92, in wrapper
    return f(*args, **kwargs)
  File "/usr/local/lib/python3.9/site-packages/airflow/cli/commands/task_command.py", line 298, in task_run
    _run_task_by_selected_method(args, dag, ti)
  File "/usr/local/lib/python3.9/site-packages/airflow/cli/commands/task_command.py", line 107, in _run_task_by_selected_method
    _run_raw_task(args, ti)
  File "/usr/local/lib/python3.9/site-packages/airflow/cli/commands/task_command.py", line 180, in _run_raw_task
    ti._run_raw_task(
  File "/usr/local/lib/python3.9/site-packages/airflow/utils/session.py", line 70, in wrapper
    return func(*args, session=session, **kwargs)
  File "/usr/local/lib/python3.9/site-packages/airflow/models/taskinstance.py", line 1334, in _run_raw_task
    self._execute_task_with_callbacks(context)
  File "/usr/local/lib/python3.9/site-packages/airflow/models/taskinstance.py", line 1460, in _execute_task_with_callbacks
    result = self._execute_task(context, self.task)
  File "/usr/local/lib/python3.9/site-packages/airflow/models/taskinstance.py", line 1516, in _execute_task
    result = execute_callable(context=context)
  File "/usr/local/lib/python3.9/site-packages/airflow/operators/bash.py", line 187, in execute
    raise AirflowException(
airflow.exceptions.AirflowException: Bash command failed. The command returned a non-zero exit code 2.
[2022-03-24 14:36:27,865] {local_task_job.py:154} INFO - Task exited with return code 1
[2022-03-24 14:36:27,900] {local_task_job.py:264} INFO - 0 downstream tasks scheduled from follow-on schedule check
