[2022-03-23 19:18:37,140] {taskinstance.py:1037} INFO - Dependencies all met for <TaskInstance: dbt_dag.model.iowa.staging_sales manual__2022-03-23T19:14:12.667416+00:00 [queued]>
[2022-03-23 19:18:37,146] {taskinstance.py:1037} INFO - Dependencies all met for <TaskInstance: dbt_dag.model.iowa.staging_sales manual__2022-03-23T19:14:12.667416+00:00 [queued]>
[2022-03-23 19:18:37,146] {taskinstance.py:1243} INFO - 
--------------------------------------------------------------------------------
[2022-03-23 19:18:37,146] {taskinstance.py:1244} INFO - Starting attempt 2 of 2
[2022-03-23 19:18:37,146] {taskinstance.py:1245} INFO - 
--------------------------------------------------------------------------------
[2022-03-23 19:18:37,154] {taskinstance.py:1264} INFO - Executing <Task(BashOperator): model.iowa.staging_sales> on 2022-03-23 19:14:12.667416+00:00
[2022-03-23 19:18:37,156] {standard_task_runner.py:52} INFO - Started process 204 to run task
[2022-03-23 19:18:37,158] {standard_task_runner.py:76} INFO - Running: ['airflow', 'tasks', 'run', 'dbt_dag', 'model.iowa.staging_sales', 'manual__2022-03-23T19:14:12.667416+00:00', '--job-id', '101', '--raw', '--subdir', 'DAGS_FOLDER/transform_dags.py', '--cfg-path', '/tmp/tmpa_5jwu5e', '--error-file', '/tmp/tmp4hacylt_']
[2022-03-23 19:18:37,159] {standard_task_runner.py:77} INFO - Job 101: Subtask model.iowa.staging_sales
[2022-03-23 19:18:37,204] {logging_mixin.py:109} INFO - Running <TaskInstance: dbt_dag.model.iowa.staging_sales manual__2022-03-23T19:14:12.667416+00:00 [running]> on host 7fae4c5ec6da
[2022-03-23 19:18:37,248] {taskinstance.py:1429} INFO - Exporting the following env vars:
AIRFLOW_CTX_DAG_OWNER=airflow
AIRFLOW_CTX_DAG_ID=dbt_dag
AIRFLOW_CTX_TASK_ID=model.iowa.staging_sales
AIRFLOW_CTX_EXECUTION_DATE=2022-03-23T19:14:12.667416+00:00
AIRFLOW_CTX_DAG_RUN_ID=manual__2022-03-23T19:14:12.667416+00:00
[2022-03-23 19:18:37,249] {subprocess.py:62} INFO - Tmp dir root location: 
 /tmp
[2022-03-23 19:18:37,249] {subprocess.py:74} INFO - Running command: ['bash', '-c', '\n            cd /opt/iowa/dbt/iowa &&\n            dbt --no-write-json run --target prod --models staging_sales\n            ']
[2022-03-23 19:18:37,254] {subprocess.py:85} INFO - Output:
[2022-03-23 19:18:39,901] {subprocess.py:89} INFO - 19:18:39  Running with dbt=1.0.4
[2022-03-23 19:18:39,923] {subprocess.py:89} INFO - 19:18:39  Unable to do partial parsing because config vars, config profile, or config target have changed
[2022-03-23 19:18:40,505] {subprocess.py:89} INFO - 19:18:40  Found 1 model, 0 tests, 0 snapshots, 0 analyses, 188 macros, 0 operations, 0 seed files, 1 source, 0 exposures, 0 metrics
[2022-03-23 19:18:40,507] {subprocess.py:89} INFO - 19:18:40
[2022-03-23 19:18:44,895] {subprocess.py:89} INFO - 19:18:44  Concurrency: 4 threads (target='prod')
[2022-03-23 19:18:44,895] {subprocess.py:89} INFO - 19:18:44
[2022-03-23 19:18:44,899] {subprocess.py:89} INFO - 19:18:44  1 of 1 START view model iowa_prod.staging_sales................................. [RUN]
[2022-03-23 19:18:48,251] {subprocess.py:89} INFO - 19:18:48  1 of 1 ERROR creating view model iowa_prod.staging_sales........................ [ERROR in 3.35s]
[2022-03-23 19:18:48,254] {subprocess.py:89} INFO - 19:18:48
[2022-03-23 19:18:48,254] {subprocess.py:89} INFO - 19:18:48  Finished running 1 view model in 7.75s.
[2022-03-23 19:18:48,255] {subprocess.py:89} INFO - 19:18:48
[2022-03-23 19:18:48,255] {subprocess.py:89} INFO - 19:18:48  Completed with 1 error and 0 warnings:
[2022-03-23 19:18:48,255] {subprocess.py:89} INFO - 19:18:48
[2022-03-23 19:18:48,256] {subprocess.py:89} INFO - 19:18:48  Database Error in model staging_sales (models/staging/staging_sales.sql)
[2022-03-23 19:18:48,256] {subprocess.py:89} INFO - 19:18:48    Invalid project ID 'iowa_project_de'. Project IDs must contain 6-63 lowercase letters, digits, or dashes. Some project IDs also include domain name separated by a colon. IDs must start with a letter and may not end with a dash.
[2022-03-23 19:18:48,257] {subprocess.py:89} INFO - 19:18:48    compiled SQL at target/run/iowa/models/staging/staging_sales.sql
[2022-03-23 19:18:48,257] {subprocess.py:89} INFO - 19:18:48
[2022-03-23 19:18:48,257] {subprocess.py:89} INFO - 19:18:48  Done. PASS=0 WARN=0 ERROR=1 SKIP=0 TOTAL=1
[2022-03-23 19:18:50,765] {subprocess.py:93} INFO - Command exited with return code 1
[2022-03-23 19:18:50,779] {taskinstance.py:1718} ERROR - Task failed with exception
Traceback (most recent call last):
  File "/usr/local/lib/python3.9/site-packages/airflow/models/taskinstance.py", line 1334, in _run_raw_task
    self._execute_task_with_callbacks(context)
  File "/usr/local/lib/python3.9/site-packages/airflow/models/taskinstance.py", line 1460, in _execute_task_with_callbacks
    result = self._execute_task(context, self.task)
  File "/usr/local/lib/python3.9/site-packages/airflow/models/taskinstance.py", line 1516, in _execute_task
    result = execute_callable(context=context)
  File "/usr/local/lib/python3.9/site-packages/airflow/operators/bash.py", line 187, in execute
    raise AirflowException(
airflow.exceptions.AirflowException: Bash command failed. The command returned a non-zero exit code 1.
[2022-03-23 19:18:50,783] {taskinstance.py:1272} INFO - Marking task as FAILED. dag_id=dbt_dag, task_id=model.iowa.staging_sales, execution_date=20220323T191412, start_date=20220323T191837, end_date=20220323T191850
[2022-03-23 19:18:50,792] {standard_task_runner.py:89} ERROR - Failed to execute job 101 for task model.iowa.staging_sales
Traceback (most recent call last):
  File "/usr/local/lib/python3.9/site-packages/airflow/task/task_runner/standard_task_runner.py", line 85, in _start_by_fork
    args.func(args, dag=self.dag)
  File "/usr/local/lib/python3.9/site-packages/airflow/cli/cli_parser.py", line 48, in command
    return func(*args, **kwargs)
  File "/usr/local/lib/python3.9/site-packages/airflow/utils/cli.py", line 92, in wrapper
    return f(*args, **kwargs)
  File "/usr/local/lib/python3.9/site-packages/airflow/cli/commands/task_command.py", line 298, in task_run
    _run_task_by_selected_method(args, dag, ti)
  File "/usr/local/lib/python3.9/site-packages/airflow/cli/commands/task_command.py", line 107, in _run_task_by_selected_method
    _run_raw_task(args, ti)
  File "/usr/local/lib/python3.9/site-packages/airflow/cli/commands/task_command.py", line 180, in _run_raw_task
    ti._run_raw_task(
  File "/usr/local/lib/python3.9/site-packages/airflow/utils/session.py", line 70, in wrapper
    return func(*args, session=session, **kwargs)
  File "/usr/local/lib/python3.9/site-packages/airflow/models/taskinstance.py", line 1334, in _run_raw_task
    self._execute_task_with_callbacks(context)
  File "/usr/local/lib/python3.9/site-packages/airflow/models/taskinstance.py", line 1460, in _execute_task_with_callbacks
    result = self._execute_task(context, self.task)
  File "/usr/local/lib/python3.9/site-packages/airflow/models/taskinstance.py", line 1516, in _execute_task
    result = execute_callable(context=context)
  File "/usr/local/lib/python3.9/site-packages/airflow/operators/bash.py", line 187, in execute
    raise AirflowException(
airflow.exceptions.AirflowException: Bash command failed. The command returned a non-zero exit code 1.
[2022-03-23 19:18:50,809] {local_task_job.py:154} INFO - Task exited with return code 1
[2022-03-23 19:18:50,840] {local_task_job.py:264} INFO - 0 downstream tasks scheduled from follow-on schedule check
