[2022-03-18 20:35:58,299] {taskinstance.py:1037} INFO - Dependencies all met for <TaskInstance: EL_dag.extract_task scheduled__2019-02-01T00:00:00+00:00 [queued]>
[2022-03-18 20:35:58,305] {taskinstance.py:1037} INFO - Dependencies all met for <TaskInstance: EL_dag.extract_task scheduled__2019-02-01T00:00:00+00:00 [queued]>
[2022-03-18 20:35:58,305] {taskinstance.py:1243} INFO - 
--------------------------------------------------------------------------------
[2022-03-18 20:35:58,305] {taskinstance.py:1244} INFO - Starting attempt 9 of 10
[2022-03-18 20:35:58,305] {taskinstance.py:1245} INFO - 
--------------------------------------------------------------------------------
[2022-03-18 20:35:58,312] {taskinstance.py:1264} INFO - Executing <Task(PythonOperator): extract_task> on 2019-02-01 00:00:00+00:00
[2022-03-18 20:35:58,316] {standard_task_runner.py:52} INFO - Started process 303 to run task
[2022-03-18 20:35:58,318] {standard_task_runner.py:76} INFO - Running: ['airflow', 'tasks', 'run', 'EL_dag', 'extract_task', 'scheduled__2019-02-01T00:00:00+00:00', '--job-id', '12', '--raw', '--subdir', 'DAGS_FOLDER/extract_load_dags.py', '--cfg-path', '/tmp/tmpoxc4f1cu', '--error-file', '/tmp/tmpwb2m0svu']
[2022-03-18 20:35:58,319] {standard_task_runner.py:77} INFO - Job 12: Subtask extract_task
[2022-03-18 20:35:58,364] {logging_mixin.py:109} INFO - Running <TaskInstance: EL_dag.extract_task scheduled__2019-02-01T00:00:00+00:00 [running]> on host cfd8f7d1d09d
[2022-03-18 20:35:58,391] {logging_mixin.py:109} WARNING - /usr/local/lib/python3.9/site-packages/airflow/utils/context.py:156 AirflowContextDeprecationWarning: Accessing 'execution_date' from the template is deprecated and will be removed in a future version. Please use 'data_interval_start' or 'logical_date' instead.
[2022-03-18 20:35:58,409] {taskinstance.py:1429} INFO - Exporting the following env vars:
AIRFLOW_CTX_DAG_OWNER=airflow
AIRFLOW_CTX_DAG_ID=EL_dag
AIRFLOW_CTX_TASK_ID=extract_task
AIRFLOW_CTX_EXECUTION_DATE=2019-02-01T00:00:00+00:00
AIRFLOW_CTX_DAG_RUN_ID=scheduled__2019-02-01T00:00:00+00:00
[2022-03-18 20:35:58,410] {logging_mixin.py:109} INFO - date................. https://data.iowa.gov/resource/m3tr-qhgy.json?$where=date ='2019-02'
[2022-03-18 20:36:00,917] {logging_mixin.py:109} INFO - the response is  200
[2022-03-18 20:36:00,917] {logging_mixin.py:109} INFO - here.........
[2022-03-18 20:36:00,951] {logging_mixin.py:109} INFO -    invoice_line_no  ...                                     store_location
0  INV-17291700004  ...                                                NaN
1  INV-17291900021  ...                                                NaN
2  INV-17286000008  ...  {'type': 'Point', 'coordinates': [-94.238806, ...
3  INV-17291600014  ...                                                NaN
4  INV-17292900006  ...                                                NaN

[5 rows x 24 columns]
[2022-03-18 20:36:00,971] {taskinstance.py:1718} ERROR - Task failed with exception
Traceback (most recent call last):
  File "/usr/local/lib/python3.9/site-packages/airflow/models/taskinstance.py", line 1334, in _run_raw_task
    self._execute_task_with_callbacks(context)
  File "/usr/local/lib/python3.9/site-packages/airflow/models/taskinstance.py", line 1460, in _execute_task_with_callbacks
    result = self._execute_task(context, self.task)
  File "/usr/local/lib/python3.9/site-packages/airflow/models/taskinstance.py", line 1516, in _execute_task
    result = execute_callable(context=context)
  File "/usr/local/lib/python3.9/site-packages/airflow/operators/python.py", line 174, in execute
    return_value = self.execute_callable()
  File "/usr/local/lib/python3.9/site-packages/airflow/operators/python.py", line 188, in execute_callable
    return self.python_callable(*self.op_args, **self.op_kwargs)
  File "/opt/iowa/airflow/dags/extract_load.py", line 16, in get_api_data
    df.to_parquet(f"../../../data/data_{date}.parquet",index=False)
  File "/usr/local/lib/python3.9/site-packages/pandas/util/_decorators.py", line 207, in wrapper
    return func(*args, **kwargs)
  File "/usr/local/lib/python3.9/site-packages/pandas/core/frame.py", line 2835, in to_parquet
    return to_parquet(
  File "/usr/local/lib/python3.9/site-packages/pandas/io/parquet.py", line 420, in to_parquet
    impl.write(
  File "/usr/local/lib/python3.9/site-packages/pandas/io/parquet.py", line 176, in write
    path_or_handle, handles, kwargs["filesystem"] = _get_path_or_handle(
  File "/usr/local/lib/python3.9/site-packages/pandas/io/parquet.py", line 102, in _get_path_or_handle
    handles = get_handle(
  File "/usr/local/lib/python3.9/site-packages/pandas/io/common.py", line 697, in get_handle
    check_parent_directory(str(handle))
  File "/usr/local/lib/python3.9/site-packages/pandas/io/common.py", line 571, in check_parent_directory
    raise OSError(fr"Cannot save file into a non-existent directory: '{parent}'")
OSError: Cannot save file into a non-existent directory: '../../../data'
[2022-03-18 20:36:00,989] {taskinstance.py:1272} INFO - Marking task as UP_FOR_RETRY. dag_id=EL_dag, task_id=extract_task, execution_date=20190201T000000, start_date=20220318T203558, end_date=20220318T203600
[2022-03-18 20:36:01,002] {standard_task_runner.py:89} ERROR - Failed to execute job 12 for task extract_task
Traceback (most recent call last):
  File "/usr/local/lib/python3.9/site-packages/airflow/task/task_runner/standard_task_runner.py", line 85, in _start_by_fork
    args.func(args, dag=self.dag)
  File "/usr/local/lib/python3.9/site-packages/airflow/cli/cli_parser.py", line 48, in command
    return func(*args, **kwargs)
  File "/usr/local/lib/python3.9/site-packages/airflow/utils/cli.py", line 92, in wrapper
    return f(*args, **kwargs)
  File "/usr/local/lib/python3.9/site-packages/airflow/cli/commands/task_command.py", line 298, in task_run
    _run_task_by_selected_method(args, dag, ti)
  File "/usr/local/lib/python3.9/site-packages/airflow/cli/commands/task_command.py", line 107, in _run_task_by_selected_method
    _run_raw_task(args, ti)
  File "/usr/local/lib/python3.9/site-packages/airflow/cli/commands/task_command.py", line 180, in _run_raw_task
    ti._run_raw_task(
  File "/usr/local/lib/python3.9/site-packages/airflow/utils/session.py", line 70, in wrapper
    return func(*args, session=session, **kwargs)
  File "/usr/local/lib/python3.9/site-packages/airflow/models/taskinstance.py", line 1334, in _run_raw_task
    self._execute_task_with_callbacks(context)
  File "/usr/local/lib/python3.9/site-packages/airflow/models/taskinstance.py", line 1460, in _execute_task_with_callbacks
    result = self._execute_task(context, self.task)
  File "/usr/local/lib/python3.9/site-packages/airflow/models/taskinstance.py", line 1516, in _execute_task
    result = execute_callable(context=context)
  File "/usr/local/lib/python3.9/site-packages/airflow/operators/python.py", line 174, in execute
    return_value = self.execute_callable()
  File "/usr/local/lib/python3.9/site-packages/airflow/operators/python.py", line 188, in execute_callable
    return self.python_callable(*self.op_args, **self.op_kwargs)
  File "/opt/iowa/airflow/dags/extract_load.py", line 16, in get_api_data
    df.to_parquet(f"../../../data/data_{date}.parquet",index=False)
  File "/usr/local/lib/python3.9/site-packages/pandas/util/_decorators.py", line 207, in wrapper
    return func(*args, **kwargs)
  File "/usr/local/lib/python3.9/site-packages/pandas/core/frame.py", line 2835, in to_parquet
    return to_parquet(
  File "/usr/local/lib/python3.9/site-packages/pandas/io/parquet.py", line 420, in to_parquet
    impl.write(
  File "/usr/local/lib/python3.9/site-packages/pandas/io/parquet.py", line 176, in write
    path_or_handle, handles, kwargs["filesystem"] = _get_path_or_handle(
  File "/usr/local/lib/python3.9/site-packages/pandas/io/parquet.py", line 102, in _get_path_or_handle
    handles = get_handle(
  File "/usr/local/lib/python3.9/site-packages/pandas/io/common.py", line 697, in get_handle
    check_parent_directory(str(handle))
  File "/usr/local/lib/python3.9/site-packages/pandas/io/common.py", line 571, in check_parent_directory
    raise OSError(fr"Cannot save file into a non-existent directory: '{parent}'")
OSError: Cannot save file into a non-existent directory: '../../../data'
[2022-03-18 20:36:01,024] {local_task_job.py:154} INFO - Task exited with return code 1
[2022-03-18 20:36:01,050] {local_task_job.py:264} INFO - 0 downstream tasks scheduled from follow-on schedule check
