[2022-03-24 12:14:54,029] {taskinstance.py:1037} INFO - Dependencies all met for <TaskInstance: dbt_dag.model.iowa.monthly_revenue manual__2022-03-23T19:14:12.667416+00:00 [queued]>
[2022-03-24 12:14:54,035] {taskinstance.py:1037} INFO - Dependencies all met for <TaskInstance: dbt_dag.model.iowa.monthly_revenue manual__2022-03-23T19:14:12.667416+00:00 [queued]>
[2022-03-24 12:14:54,035] {taskinstance.py:1243} INFO - 
--------------------------------------------------------------------------------
[2022-03-24 12:14:54,035] {taskinstance.py:1244} INFO - Starting attempt 2 of 2
[2022-03-24 12:14:54,035] {taskinstance.py:1245} INFO - 
--------------------------------------------------------------------------------
[2022-03-24 12:14:54,043] {taskinstance.py:1264} INFO - Executing <Task(BashOperator): model.iowa.monthly_revenue> on 2022-03-23 19:14:12.667416+00:00
[2022-03-24 12:14:54,044] {standard_task_runner.py:52} INFO - Started process 1027 to run task
[2022-03-24 12:14:54,047] {standard_task_runner.py:76} INFO - Running: ['airflow', 'tasks', 'run', 'dbt_dag', 'model.iowa.monthly_revenue', 'manual__2022-03-23T19:14:12.667416+00:00', '--job-id', '148', '--raw', '--subdir', 'DAGS_FOLDER/transform_dags.py', '--cfg-path', '/tmp/tmp5__f95ew', '--error-file', '/tmp/tmpcnzkzmxi']
[2022-03-24 12:14:54,048] {standard_task_runner.py:77} INFO - Job 148: Subtask model.iowa.monthly_revenue
[2022-03-24 12:14:54,094] {logging_mixin.py:109} INFO - Running <TaskInstance: dbt_dag.model.iowa.monthly_revenue manual__2022-03-23T19:14:12.667416+00:00 [running]> on host a91ac75a8f43
[2022-03-24 12:14:54,138] {taskinstance.py:1429} INFO - Exporting the following env vars:
AIRFLOW_CTX_DAG_OWNER=airflow
AIRFLOW_CTX_DAG_ID=dbt_dag
AIRFLOW_CTX_TASK_ID=model.iowa.monthly_revenue
AIRFLOW_CTX_EXECUTION_DATE=2022-03-23T19:14:12.667416+00:00
AIRFLOW_CTX_DAG_RUN_ID=manual__2022-03-23T19:14:12.667416+00:00
[2022-03-24 12:14:54,138] {subprocess.py:62} INFO - Tmp dir root location: 
 /tmp
[2022-03-24 12:14:54,139] {subprocess.py:74} INFO - Running command: ['bash', '-c', '\n            cd /opt/iowa/dbt/iowa &&\n            dbt --no-write-json run --target dev --models monthly_revenue\n            ']
[2022-03-24 12:14:54,144] {subprocess.py:85} INFO - Output:
[2022-03-24 12:14:57,022] {subprocess.py:89} INFO - 12:14:57  Running with dbt=1.0.4
[2022-03-24 12:14:57,064] {subprocess.py:89} INFO - 12:14:57  Found 5 models, 0 tests, 0 snapshots, 0 analyses, 188 macros, 0 operations, 0 seed files, 1 source, 0 exposures, 0 metrics
[2022-03-24 12:14:57,067] {subprocess.py:89} INFO - 12:14:57
[2022-03-24 12:15:02,888] {subprocess.py:89} INFO - 12:15:02  Concurrency: 4 threads (target='dev')
[2022-03-24 12:15:02,889] {subprocess.py:89} INFO - 12:15:02
[2022-03-24 12:15:02,893] {subprocess.py:89} INFO - 12:15:02  1 of 1 START incremental model iowa_staging.monthly_revenue..................... [RUN]
[2022-03-24 12:15:07,220] {subprocess.py:89} INFO - 12:15:07  1 of 1 ERROR creating incremental model iowa_staging.monthly_revenue............ [ERROR in 4.33s]
[2022-03-24 12:15:07,223] {subprocess.py:89} INFO - 12:15:07
[2022-03-24 12:15:07,223] {subprocess.py:89} INFO - 12:15:07  Finished running 1 incremental model in 10.16s.
[2022-03-24 12:15:07,224] {subprocess.py:89} INFO - 12:15:07
[2022-03-24 12:15:07,224] {subprocess.py:89} INFO - 12:15:07  Completed with 1 error and 0 warnings:
[2022-03-24 12:15:07,225] {subprocess.py:89} INFO - 12:15:07
[2022-03-24 12:15:07,225] {subprocess.py:89} INFO - 12:15:07  Database Error in model monthly_revenue (models/marts/sales/monthly_revenue.sql)
[2022-03-24 12:15:07,225] {subprocess.py:89} INFO - 12:15:07    Syntax error: Expected ")" but got ";" at [19:15]
[2022-03-24 12:15:07,226] {subprocess.py:89} INFO - 12:15:07    compiled SQL at target/run/iowa/models/marts/sales/monthly_revenue.sql
[2022-03-24 12:15:07,226] {subprocess.py:89} INFO - 12:15:07
[2022-03-24 12:15:07,226] {subprocess.py:89} INFO - 12:15:07  Done. PASS=0 WARN=0 ERROR=1 SKIP=0 TOTAL=1
[2022-03-24 12:15:09,481] {subprocess.py:93} INFO - Command exited with return code 1
[2022-03-24 12:15:09,493] {taskinstance.py:1718} ERROR - Task failed with exception
Traceback (most recent call last):
  File "/usr/local/lib/python3.9/site-packages/airflow/models/taskinstance.py", line 1334, in _run_raw_task
    self._execute_task_with_callbacks(context)
  File "/usr/local/lib/python3.9/site-packages/airflow/models/taskinstance.py", line 1460, in _execute_task_with_callbacks
    result = self._execute_task(context, self.task)
  File "/usr/local/lib/python3.9/site-packages/airflow/models/taskinstance.py", line 1516, in _execute_task
    result = execute_callable(context=context)
  File "/usr/local/lib/python3.9/site-packages/airflow/operators/bash.py", line 187, in execute
    raise AirflowException(
airflow.exceptions.AirflowException: Bash command failed. The command returned a non-zero exit code 1.
[2022-03-24 12:15:09,497] {taskinstance.py:1272} INFO - Marking task as FAILED. dag_id=dbt_dag, task_id=model.iowa.monthly_revenue, execution_date=20220323T191412, start_date=20220324T121454, end_date=20220324T121509
[2022-03-24 12:15:09,506] {standard_task_runner.py:89} ERROR - Failed to execute job 148 for task model.iowa.monthly_revenue
Traceback (most recent call last):
  File "/usr/local/lib/python3.9/site-packages/airflow/task/task_runner/standard_task_runner.py", line 85, in _start_by_fork
    args.func(args, dag=self.dag)
  File "/usr/local/lib/python3.9/site-packages/airflow/cli/cli_parser.py", line 48, in command
    return func(*args, **kwargs)
  File "/usr/local/lib/python3.9/site-packages/airflow/utils/cli.py", line 92, in wrapper
    return f(*args, **kwargs)
  File "/usr/local/lib/python3.9/site-packages/airflow/cli/commands/task_command.py", line 298, in task_run
    _run_task_by_selected_method(args, dag, ti)
  File "/usr/local/lib/python3.9/site-packages/airflow/cli/commands/task_command.py", line 107, in _run_task_by_selected_method
    _run_raw_task(args, ti)
  File "/usr/local/lib/python3.9/site-packages/airflow/cli/commands/task_command.py", line 180, in _run_raw_task
    ti._run_raw_task(
  File "/usr/local/lib/python3.9/site-packages/airflow/utils/session.py", line 70, in wrapper
    return func(*args, session=session, **kwargs)
  File "/usr/local/lib/python3.9/site-packages/airflow/models/taskinstance.py", line 1334, in _run_raw_task
    self._execute_task_with_callbacks(context)
  File "/usr/local/lib/python3.9/site-packages/airflow/models/taskinstance.py", line 1460, in _execute_task_with_callbacks
    result = self._execute_task(context, self.task)
  File "/usr/local/lib/python3.9/site-packages/airflow/models/taskinstance.py", line 1516, in _execute_task
    result = execute_callable(context=context)
  File "/usr/local/lib/python3.9/site-packages/airflow/operators/bash.py", line 187, in execute
    raise AirflowException(
airflow.exceptions.AirflowException: Bash command failed. The command returned a non-zero exit code 1.
[2022-03-24 12:15:09,542] {local_task_job.py:154} INFO - Task exited with return code 1
[2022-03-24 12:15:09,570] {local_task_job.py:264} INFO - 0 downstream tasks scheduled from follow-on schedule check
