[2022-03-21 10:55:40,405] {taskinstance.py:1037} INFO - Dependencies all met for <TaskInstance: EL_dag.local_to_gcs_task scheduled__2012-02-02T01:00:00+00:00 [queued]>
[2022-03-21 10:55:40,412] {taskinstance.py:1037} INFO - Dependencies all met for <TaskInstance: EL_dag.local_to_gcs_task scheduled__2012-02-02T01:00:00+00:00 [queued]>
[2022-03-21 10:55:40,412] {taskinstance.py:1243} INFO - 
--------------------------------------------------------------------------------
[2022-03-21 10:55:40,412] {taskinstance.py:1244} INFO - Starting attempt 1 of 2
[2022-03-21 10:55:40,412] {taskinstance.py:1245} INFO - 
--------------------------------------------------------------------------------
[2022-03-21 10:55:40,419] {taskinstance.py:1264} INFO - Executing <Task(PythonOperator): local_to_gcs_task> on 2012-02-02 01:00:00+00:00
[2022-03-21 10:55:40,423] {standard_task_runner.py:52} INFO - Started process 450 to run task
[2022-03-21 10:55:40,426] {standard_task_runner.py:76} INFO - Running: ['airflow', 'tasks', 'run', 'EL_dag', 'local_to_gcs_task', 'scheduled__2012-02-02T01:00:00+00:00', '--job-id', '8', '--raw', '--subdir', 'DAGS_FOLDER/extract_load_dags.py', '--cfg-path', '/tmp/tmpzqzzmbfl', '--error-file', '/tmp/tmpt9wzvadz']
[2022-03-21 10:55:40,427] {standard_task_runner.py:77} INFO - Job 8: Subtask local_to_gcs_task
[2022-03-21 10:55:40,487] {logging_mixin.py:109} INFO - Running <TaskInstance: EL_dag.local_to_gcs_task scheduled__2012-02-02T01:00:00+00:00 [running]> on host 5908b9c456cd
[2022-03-21 10:55:40,594] {logging_mixin.py:109} WARNING - /usr/local/lib/python3.9/site-packages/airflow/utils/context.py:156 AirflowContextDeprecationWarning: Accessing 'execution_date' from the template is deprecated and will be removed in a future version. Please use 'data_interval_start' or 'logical_date' instead.
[2022-03-21 10:55:40,615] {taskinstance.py:1429} INFO - Exporting the following env vars:
AIRFLOW_CTX_DAG_OWNER=airflow
AIRFLOW_CTX_DAG_ID=EL_dag
AIRFLOW_CTX_TASK_ID=local_to_gcs_task
AIRFLOW_CTX_EXECUTION_DATE=2012-02-02T01:00:00+00:00
AIRFLOW_CTX_DAG_RUN_ID=scheduled__2012-02-02T01:00:00+00:00
[2022-03-21 10:55:54,955] {python.py:175} INFO - Done. Returned value was: None
[2022-03-21 10:55:54,968] {taskinstance.py:1272} INFO - Marking task as SUCCESS. dag_id=EL_dag, task_id=local_to_gcs_task, execution_date=20120202T010000, start_date=20220321T105540, end_date=20220321T105554
[2022-03-21 10:55:55,008] {local_task_job.py:154} INFO - Task exited with return code 0
[2022-03-21 10:55:55,035] {local_task_job.py:264} INFO - 1 downstream tasks scheduled from follow-on schedule check
[2022-03-21 21:32:55,905] {taskinstance.py:1037} INFO - Dependencies all met for <TaskInstance: EL_dag.local_to_gcs_task scheduled__2012-02-02T01:00:00+00:00 [queued]>
[2022-03-21 21:32:55,915] {taskinstance.py:1037} INFO - Dependencies all met for <TaskInstance: EL_dag.local_to_gcs_task scheduled__2012-02-02T01:00:00+00:00 [queued]>
[2022-03-21 21:32:55,915] {taskinstance.py:1243} INFO - 
--------------------------------------------------------------------------------
[2022-03-21 21:32:55,915] {taskinstance.py:1244} INFO - Starting attempt 1 of 2
[2022-03-21 21:32:55,915] {taskinstance.py:1245} INFO - 
--------------------------------------------------------------------------------
[2022-03-21 21:32:55,932] {taskinstance.py:1264} INFO - Executing <Task(PythonOperator): local_to_gcs_task> on 2012-02-02 01:00:00+00:00
[2022-03-21 21:32:55,936] {standard_task_runner.py:52} INFO - Started process 2028 to run task
[2022-03-21 21:32:55,938] {standard_task_runner.py:76} INFO - Running: ['airflow', 'tasks', 'run', 'EL_dag', 'local_to_gcs_task', 'scheduled__2012-02-02T01:00:00+00:00', '--job-id', '32', '--raw', '--subdir', 'DAGS_FOLDER/extract_load_dags.py', '--cfg-path', '/tmp/tmp8k4qjg07', '--error-file', '/tmp/tmposmhv2jw']
[2022-03-21 21:32:55,939] {standard_task_runner.py:77} INFO - Job 32: Subtask local_to_gcs_task
[2022-03-21 21:32:56,060] {logging_mixin.py:109} INFO - Running <TaskInstance: EL_dag.local_to_gcs_task scheduled__2012-02-02T01:00:00+00:00 [running]> on host 7fae4c5ec6da
[2022-03-21 21:32:56,095] {logging_mixin.py:109} WARNING - /usr/local/lib/python3.9/site-packages/airflow/utils/context.py:156 AirflowContextDeprecationWarning: Accessing 'execution_date' from the template is deprecated and will be removed in a future version. Please use 'data_interval_start' or 'logical_date' instead.
[2022-03-21 21:32:56,118] {taskinstance.py:1429} INFO - Exporting the following env vars:
AIRFLOW_CTX_DAG_OWNER=airflow
AIRFLOW_CTX_DAG_ID=EL_dag
AIRFLOW_CTX_TASK_ID=local_to_gcs_task
AIRFLOW_CTX_EXECUTION_DATE=2012-02-02T01:00:00+00:00
AIRFLOW_CTX_DAG_RUN_ID=scheduled__2012-02-02T01:00:00+00:00
[2022-03-21 21:32:56,130] {taskinstance.py:1718} ERROR - Task failed with exception
Traceback (most recent call last):
  File "/usr/local/lib/python3.9/site-packages/airflow/models/taskinstance.py", line 1334, in _run_raw_task
    self._execute_task_with_callbacks(context)
  File "/usr/local/lib/python3.9/site-packages/airflow/models/taskinstance.py", line 1460, in _execute_task_with_callbacks
    result = self._execute_task(context, self.task)
  File "/usr/local/lib/python3.9/site-packages/airflow/models/taskinstance.py", line 1516, in _execute_task
    result = execute_callable(context=context)
  File "/usr/local/lib/python3.9/site-packages/airflow/operators/python.py", line 174, in execute
    return_value = self.execute_callable()
  File "/usr/local/lib/python3.9/site-packages/airflow/operators/python.py", line 188, in execute_callable
    return self.python_callable(*self.op_args, **self.op_kwargs)
  File "/opt/iowa/airflow/dags/extract_load.py", line 48, in upload_to_gcs
    blob.upload_from_filename(local_file)
  File "/usr/local/lib/python3.9/site-packages/google/cloud/storage/blob.py", line 2720, in upload_from_filename
    with open(filename, "rb") as file_obj:
FileNotFoundError: [Errno 2] No such file or directory: '../data/data_2012-02.parquet'
[2022-03-21 21:32:56,143] {taskinstance.py:1272} INFO - Marking task as UP_FOR_RETRY. dag_id=EL_dag, task_id=local_to_gcs_task, execution_date=20120202T010000, start_date=20220321T213255, end_date=20220321T213256
[2022-03-21 21:32:56,153] {standard_task_runner.py:89} ERROR - Failed to execute job 32 for task local_to_gcs_task
Traceback (most recent call last):
  File "/usr/local/lib/python3.9/site-packages/airflow/task/task_runner/standard_task_runner.py", line 85, in _start_by_fork
    args.func(args, dag=self.dag)
  File "/usr/local/lib/python3.9/site-packages/airflow/cli/cli_parser.py", line 48, in command
    return func(*args, **kwargs)
  File "/usr/local/lib/python3.9/site-packages/airflow/utils/cli.py", line 92, in wrapper
    return f(*args, **kwargs)
  File "/usr/local/lib/python3.9/site-packages/airflow/cli/commands/task_command.py", line 298, in task_run
    _run_task_by_selected_method(args, dag, ti)
  File "/usr/local/lib/python3.9/site-packages/airflow/cli/commands/task_command.py", line 107, in _run_task_by_selected_method
    _run_raw_task(args, ti)
  File "/usr/local/lib/python3.9/site-packages/airflow/cli/commands/task_command.py", line 180, in _run_raw_task
    ti._run_raw_task(
  File "/usr/local/lib/python3.9/site-packages/airflow/utils/session.py", line 70, in wrapper
    return func(*args, session=session, **kwargs)
  File "/usr/local/lib/python3.9/site-packages/airflow/models/taskinstance.py", line 1334, in _run_raw_task
    self._execute_task_with_callbacks(context)
  File "/usr/local/lib/python3.9/site-packages/airflow/models/taskinstance.py", line 1460, in _execute_task_with_callbacks
    result = self._execute_task(context, self.task)
  File "/usr/local/lib/python3.9/site-packages/airflow/models/taskinstance.py", line 1516, in _execute_task
    result = execute_callable(context=context)
  File "/usr/local/lib/python3.9/site-packages/airflow/operators/python.py", line 174, in execute
    return_value = self.execute_callable()
  File "/usr/local/lib/python3.9/site-packages/airflow/operators/python.py", line 188, in execute_callable
    return self.python_callable(*self.op_args, **self.op_kwargs)
  File "/opt/iowa/airflow/dags/extract_load.py", line 48, in upload_to_gcs
    blob.upload_from_filename(local_file)
  File "/usr/local/lib/python3.9/site-packages/google/cloud/storage/blob.py", line 2720, in upload_from_filename
    with open(filename, "rb") as file_obj:
FileNotFoundError: [Errno 2] No such file or directory: '../data/data_2012-02.parquet'
[2022-03-21 21:32:56,191] {local_task_job.py:154} INFO - Task exited with return code 1
[2022-03-21 21:32:56,277] {local_task_job.py:264} INFO - 0 downstream tasks scheduled from follow-on schedule check
