[2022-03-21 21:11:13,350] {taskinstance.py:1037} INFO - Dependencies all met for <TaskInstance: dbt_dag.model.iowa.staging_sales scheduled__2021-01-02T01:00:00+00:00 [queued]>
[2022-03-21 21:11:13,361] {taskinstance.py:1037} INFO - Dependencies all met for <TaskInstance: dbt_dag.model.iowa.staging_sales scheduled__2021-01-02T01:00:00+00:00 [queued]>
[2022-03-21 21:11:13,362] {taskinstance.py:1243} INFO - 
--------------------------------------------------------------------------------
[2022-03-21 21:11:13,362] {taskinstance.py:1244} INFO - Starting attempt 1 of 1
[2022-03-21 21:11:13,362] {taskinstance.py:1245} INFO - 
--------------------------------------------------------------------------------
[2022-03-21 21:11:13,374] {taskinstance.py:1264} INFO - Executing <Task(BashOperator): model.iowa.staging_sales> on 2021-01-02 01:00:00+00:00
[2022-03-21 21:11:13,377] {standard_task_runner.py:52} INFO - Started process 491 to run task
[2022-03-21 21:11:13,380] {standard_task_runner.py:76} INFO - Running: ['airflow', 'tasks', 'run', 'dbt_dag', 'model.iowa.staging_sales', 'scheduled__2021-01-02T01:00:00+00:00', '--job-id', '6', '--raw', '--subdir', 'DAGS_FOLDER/transform_dags.py', '--cfg-path', '/tmp/tmpqjql02uy', '--error-file', '/tmp/tmp1oz9ijjq']
[2022-03-21 21:11:13,381] {standard_task_runner.py:77} INFO - Job 6: Subtask model.iowa.staging_sales
[2022-03-21 21:11:13,453] {logging_mixin.py:109} INFO - Running <TaskInstance: dbt_dag.model.iowa.staging_sales scheduled__2021-01-02T01:00:00+00:00 [running]> on host 7fae4c5ec6da
[2022-03-21 21:11:13,518] {taskinstance.py:1429} INFO - Exporting the following env vars:
AIRFLOW_CTX_DAG_OWNER=airflow
AIRFLOW_CTX_DAG_ID=dbt_dag
AIRFLOW_CTX_TASK_ID=model.iowa.staging_sales
AIRFLOW_CTX_EXECUTION_DATE=2021-01-02T01:00:00+00:00
AIRFLOW_CTX_DAG_RUN_ID=scheduled__2021-01-02T01:00:00+00:00
[2022-03-21 21:11:13,519] {subprocess.py:62} INFO - Tmp dir root location: 
 /tmp
[2022-03-21 21:11:13,520] {subprocess.py:74} INFO - Running command: ['bash', '-c', '\n            cd /opt/iowa/dbt/iowa &&\n            dbt --no-write-json run --target prod --models staging_sales\n            ']
[2022-03-21 21:11:13,526] {subprocess.py:85} INFO - Output:
[2022-03-21 21:11:29,192] {subprocess.py:89} INFO - 21:11:29  Running with dbt=1.0.4
[2022-03-21 21:11:29,277] {subprocess.py:89} INFO - 21:11:29  Unable to do partial parsing because config vars, config profile, or config target have changed
[2022-03-21 21:11:30,334] {subprocess.py:89} INFO - 21:11:30  Found 1 model, 0 tests, 0 snapshots, 0 analyses, 188 macros, 0 operations, 0 seed files, 1 source, 0 exposures, 0 metrics
[2022-03-21 21:11:30,338] {subprocess.py:89} INFO - 21:11:30
[2022-03-21 21:11:38,456] {subprocess.py:89} INFO - 21:11:38  Concurrency: 4 threads (target='prod')
[2022-03-21 21:11:38,457] {subprocess.py:89} INFO - 21:11:38
[2022-03-21 21:11:38,461] {subprocess.py:89} INFO - 21:11:38  1 of 1 START view model iowa_prod.staging_sales................................. [RUN]
[2022-03-21 21:11:42,228] {subprocess.py:89} INFO - 21:11:42  1 of 1 ERROR creating view model iowa_prod.staging_sales........................ [ERROR in 3.77s]
[2022-03-21 21:11:42,231] {subprocess.py:89} INFO - 21:11:42
[2022-03-21 21:11:42,231] {subprocess.py:89} INFO - 21:11:42  Finished running 1 view model in 11.89s.
[2022-03-21 21:11:42,232] {subprocess.py:89} INFO - 21:11:42
[2022-03-21 21:11:42,233] {subprocess.py:89} INFO - 21:11:42  Completed with 1 error and 0 warnings:
[2022-03-21 21:11:42,233] {subprocess.py:89} INFO - 21:11:42
[2022-03-21 21:11:42,233] {subprocess.py:89} INFO - 21:11:42  Database Error in model staging_sales (models/staging/staging_sales.sql)
[2022-03-21 21:11:42,234] {subprocess.py:89} INFO - 21:11:42    Invalid project ID 'iowa_project_de'. Project IDs must contain 6-63 lowercase letters, digits, or dashes. Some project IDs also include domain name separated by a colon. IDs must start with a letter and may not end with a dash.
[2022-03-21 21:11:42,234] {subprocess.py:89} INFO - 21:11:42    compiled SQL at target/run/iowa/models/staging/staging_sales.sql
[2022-03-21 21:11:42,235] {subprocess.py:89} INFO - 21:11:42
[2022-03-21 21:11:42,235] {subprocess.py:89} INFO - 21:11:42  Done. PASS=0 WARN=0 ERROR=1 SKIP=0 TOTAL=1
[2022-03-21 21:11:44,346] {subprocess.py:93} INFO - Command exited with return code 1
[2022-03-21 21:11:44,360] {taskinstance.py:1718} ERROR - Task failed with exception
Traceback (most recent call last):
  File "/usr/local/lib/python3.9/site-packages/airflow/models/taskinstance.py", line 1334, in _run_raw_task
    self._execute_task_with_callbacks(context)
  File "/usr/local/lib/python3.9/site-packages/airflow/models/taskinstance.py", line 1460, in _execute_task_with_callbacks
    result = self._execute_task(context, self.task)
  File "/usr/local/lib/python3.9/site-packages/airflow/models/taskinstance.py", line 1516, in _execute_task
    result = execute_callable(context=context)
  File "/usr/local/lib/python3.9/site-packages/airflow/operators/bash.py", line 187, in execute
    raise AirflowException(
airflow.exceptions.AirflowException: Bash command failed. The command returned a non-zero exit code 1.
[2022-03-21 21:11:44,366] {taskinstance.py:1272} INFO - Marking task as FAILED. dag_id=dbt_dag, task_id=model.iowa.staging_sales, execution_date=20210102T010000, start_date=20220321T211113, end_date=20220321T211144
[2022-03-21 21:11:44,382] {standard_task_runner.py:89} ERROR - Failed to execute job 6 for task model.iowa.staging_sales
Traceback (most recent call last):
  File "/usr/local/lib/python3.9/site-packages/airflow/task/task_runner/standard_task_runner.py", line 85, in _start_by_fork
    args.func(args, dag=self.dag)
  File "/usr/local/lib/python3.9/site-packages/airflow/cli/cli_parser.py", line 48, in command
    return func(*args, **kwargs)
  File "/usr/local/lib/python3.9/site-packages/airflow/utils/cli.py", line 92, in wrapper
    return f(*args, **kwargs)
  File "/usr/local/lib/python3.9/site-packages/airflow/cli/commands/task_command.py", line 298, in task_run
    _run_task_by_selected_method(args, dag, ti)
  File "/usr/local/lib/python3.9/site-packages/airflow/cli/commands/task_command.py", line 107, in _run_task_by_selected_method
    _run_raw_task(args, ti)
  File "/usr/local/lib/python3.9/site-packages/airflow/cli/commands/task_command.py", line 180, in _run_raw_task
    ti._run_raw_task(
  File "/usr/local/lib/python3.9/site-packages/airflow/utils/session.py", line 70, in wrapper
    return func(*args, session=session, **kwargs)
  File "/usr/local/lib/python3.9/site-packages/airflow/models/taskinstance.py", line 1334, in _run_raw_task
    self._execute_task_with_callbacks(context)
  File "/usr/local/lib/python3.9/site-packages/airflow/models/taskinstance.py", line 1460, in _execute_task_with_callbacks
    result = self._execute_task(context, self.task)
  File "/usr/local/lib/python3.9/site-packages/airflow/models/taskinstance.py", line 1516, in _execute_task
    result = execute_callable(context=context)
  File "/usr/local/lib/python3.9/site-packages/airflow/operators/bash.py", line 187, in execute
    raise AirflowException(
airflow.exceptions.AirflowException: Bash command failed. The command returned a non-zero exit code 1.
[2022-03-21 21:11:44,419] {local_task_job.py:154} INFO - Task exited with return code 1
[2022-03-21 21:11:44,461] {local_task_job.py:264} INFO - 0 downstream tasks scheduled from follow-on schedule check
