[2022-03-21 10:55:24,161] {taskinstance.py:1037} INFO - Dependencies all met for <TaskInstance: EL_dag.bigquery_external_dataset_task scheduled__2012-02-02T01:00:00+00:00 [queued]>
[2022-03-21 10:55:24,168] {taskinstance.py:1037} INFO - Dependencies all met for <TaskInstance: EL_dag.bigquery_external_dataset_task scheduled__2012-02-02T01:00:00+00:00 [queued]>
[2022-03-21 10:55:24,168] {taskinstance.py:1243} INFO - 
--------------------------------------------------------------------------------
[2022-03-21 10:55:24,169] {taskinstance.py:1244} INFO - Starting attempt 1 of 2
[2022-03-21 10:55:24,169] {taskinstance.py:1245} INFO - 
--------------------------------------------------------------------------------
[2022-03-21 10:55:24,176] {taskinstance.py:1264} INFO - Executing <Task(BigQueryCreateExternalTableOperator): bigquery_external_dataset_task> on 2012-02-02 01:00:00+00:00
[2022-03-21 10:55:24,179] {standard_task_runner.py:52} INFO - Started process 435 to run task
[2022-03-21 10:55:24,181] {standard_task_runner.py:76} INFO - Running: ['airflow', 'tasks', 'run', 'EL_dag', 'bigquery_external_dataset_task', 'scheduled__2012-02-02T01:00:00+00:00', '--job-id', '6', '--raw', '--subdir', 'DAGS_FOLDER/extract_load_dags.py', '--cfg-path', '/tmp/tmpxpq4yb6h', '--error-file', '/tmp/tmp8a0fnoga']
[2022-03-21 10:55:24,182] {standard_task_runner.py:77} INFO - Job 6: Subtask bigquery_external_dataset_task
[2022-03-21 10:55:24,233] {logging_mixin.py:109} INFO - Running <TaskInstance: EL_dag.bigquery_external_dataset_task scheduled__2012-02-02T01:00:00+00:00 [running]> on host 5908b9c456cd
[2022-03-21 10:55:24,365] {taskinstance.py:1429} INFO - Exporting the following env vars:
AIRFLOW_CTX_DAG_OWNER=airflow
AIRFLOW_CTX_DAG_ID=EL_dag
AIRFLOW_CTX_TASK_ID=bigquery_external_dataset_task
AIRFLOW_CTX_EXECUTION_DATE=2012-02-02T01:00:00+00:00
AIRFLOW_CTX_DAG_RUN_ID=scheduled__2012-02-02T01:00:00+00:00
[2022-03-21 10:55:24,366] {crypto.py:82} WARNING - empty cryptography key - values will not be stored encrypted.
[2022-03-21 10:55:28,902] {taskinstance.py:1718} ERROR - Task failed with exception
Traceback (most recent call last):
  File "/usr/local/lib/python3.9/site-packages/airflow/models/taskinstance.py", line 1334, in _run_raw_task
    self._execute_task_with_callbacks(context)
  File "/usr/local/lib/python3.9/site-packages/airflow/models/taskinstance.py", line 1460, in _execute_task_with_callbacks
    result = self._execute_task(context, self.task)
  File "/usr/local/lib/python3.9/site-packages/airflow/models/taskinstance.py", line 1516, in _execute_task
    result = execute_callable(context=context)
  File "/usr/local/lib/python3.9/site-packages/airflow/providers/google/cloud/operators/bigquery.py", line 1113, in execute
    bq_hook.create_empty_table(
  File "/usr/local/lib/python3.9/site-packages/airflow/providers/google/common/hooks/base_google.py", line 433, in inner_wrapper
    return func(self, *args, **kwargs)
  File "/usr/local/lib/python3.9/site-packages/airflow/providers/google/cloud/hooks/bigquery.py", line 416, in create_empty_table
    return self.get_client(project_id=project_id, location=location).create_table(
  File "/usr/local/lib/python3.9/site-packages/google/cloud/bigquery/client.py", line 748, in create_table
    api_response = self._call_api(
  File "/usr/local/lib/python3.9/site-packages/google/cloud/bigquery/client.py", line 782, in _call_api
    return call()
  File "/usr/local/lib/python3.9/site-packages/google/api_core/retry.py", line 286, in retry_wrapped_func
    return retry_target(
  File "/usr/local/lib/python3.9/site-packages/google/api_core/retry.py", line 189, in retry_target
    return target()
  File "/usr/local/lib/python3.9/site-packages/google/cloud/_http.py", line 484, in api_request
    raise exceptions.from_http_response(response)
google.api_core.exceptions.BadRequest: 400 POST https://bigquery.googleapis.com/bigquery/v2/projects/iowa-project-de/datasets/iowa_data/tables?prettyPrint=false: Error while reading table: raw_data, error message: Failed to expand table raw_data with file pattern gs://iowa_data_lake/raw/iowa_sales/*: matched no files.
[2022-03-21 10:55:28,918] {taskinstance.py:1272} INFO - Marking task as UP_FOR_RETRY. dag_id=EL_dag, task_id=bigquery_external_dataset_task, execution_date=20120202T010000, start_date=20220321T105524, end_date=20220321T105528
[2022-03-21 10:55:28,928] {standard_task_runner.py:89} ERROR - Failed to execute job 6 for task bigquery_external_dataset_task
Traceback (most recent call last):
  File "/usr/local/lib/python3.9/site-packages/airflow/task/task_runner/standard_task_runner.py", line 85, in _start_by_fork
    args.func(args, dag=self.dag)
  File "/usr/local/lib/python3.9/site-packages/airflow/cli/cli_parser.py", line 48, in command
    return func(*args, **kwargs)
  File "/usr/local/lib/python3.9/site-packages/airflow/utils/cli.py", line 92, in wrapper
    return f(*args, **kwargs)
  File "/usr/local/lib/python3.9/site-packages/airflow/cli/commands/task_command.py", line 298, in task_run
    _run_task_by_selected_method(args, dag, ti)
  File "/usr/local/lib/python3.9/site-packages/airflow/cli/commands/task_command.py", line 107, in _run_task_by_selected_method
    _run_raw_task(args, ti)
  File "/usr/local/lib/python3.9/site-packages/airflow/cli/commands/task_command.py", line 180, in _run_raw_task
    ti._run_raw_task(
  File "/usr/local/lib/python3.9/site-packages/airflow/utils/session.py", line 70, in wrapper
    return func(*args, session=session, **kwargs)
  File "/usr/local/lib/python3.9/site-packages/airflow/models/taskinstance.py", line 1334, in _run_raw_task
    self._execute_task_with_callbacks(context)
  File "/usr/local/lib/python3.9/site-packages/airflow/models/taskinstance.py", line 1460, in _execute_task_with_callbacks
    result = self._execute_task(context, self.task)
  File "/usr/local/lib/python3.9/site-packages/airflow/models/taskinstance.py", line 1516, in _execute_task
    result = execute_callable(context=context)
  File "/usr/local/lib/python3.9/site-packages/airflow/providers/google/cloud/operators/bigquery.py", line 1113, in execute
    bq_hook.create_empty_table(
  File "/usr/local/lib/python3.9/site-packages/airflow/providers/google/common/hooks/base_google.py", line 433, in inner_wrapper
    return func(self, *args, **kwargs)
  File "/usr/local/lib/python3.9/site-packages/airflow/providers/google/cloud/hooks/bigquery.py", line 416, in create_empty_table
    return self.get_client(project_id=project_id, location=location).create_table(
  File "/usr/local/lib/python3.9/site-packages/google/cloud/bigquery/client.py", line 748, in create_table
    api_response = self._call_api(
  File "/usr/local/lib/python3.9/site-packages/google/cloud/bigquery/client.py", line 782, in _call_api
    return call()
  File "/usr/local/lib/python3.9/site-packages/google/api_core/retry.py", line 286, in retry_wrapped_func
    return retry_target(
  File "/usr/local/lib/python3.9/site-packages/google/api_core/retry.py", line 189, in retry_target
    return target()
  File "/usr/local/lib/python3.9/site-packages/google/cloud/_http.py", line 484, in api_request
    raise exceptions.from_http_response(response)
google.api_core.exceptions.BadRequest: 400 POST https://bigquery.googleapis.com/bigquery/v2/projects/iowa-project-de/datasets/iowa_data/tables?prettyPrint=false: Error while reading table: raw_data, error message: Failed to expand table raw_data with file pattern gs://iowa_data_lake/raw/iowa_sales/*: matched no files.
[2022-03-21 10:55:28,970] {local_task_job.py:154} INFO - Task exited with return code 1
[2022-03-21 10:55:28,996] {local_task_job.py:264} INFO - 0 downstream tasks scheduled from follow-on schedule check
