[2022-03-21 21:52:51,522] {taskinstance.py:1037} INFO - Dependencies all met for <TaskInstance: BQ_dag.external_task_sensor scheduled__2012-01-01T00:00:00+00:00 [queued]>
[2022-03-21 21:52:51,528] {taskinstance.py:1037} INFO - Dependencies all met for <TaskInstance: BQ_dag.external_task_sensor scheduled__2012-01-01T00:00:00+00:00 [queued]>
[2022-03-21 21:52:51,528] {taskinstance.py:1243} INFO - 
--------------------------------------------------------------------------------
[2022-03-21 21:52:51,528] {taskinstance.py:1244} INFO - Starting attempt 2 of 4
[2022-03-21 21:52:51,529] {taskinstance.py:1245} INFO - 
--------------------------------------------------------------------------------
[2022-03-21 21:52:51,535] {taskinstance.py:1264} INFO - Executing <Task(ExternalTaskSensor): external_task_sensor> on 2012-01-01 00:00:00+00:00
[2022-03-21 21:52:51,539] {standard_task_runner.py:52} INFO - Started process 3169 to run task
[2022-03-21 21:52:51,541] {standard_task_runner.py:76} INFO - Running: ['airflow', 'tasks', 'run', 'BQ_dag', 'external_task_sensor', 'scheduled__2012-01-01T00:00:00+00:00', '--job-id', '46', '--raw', '--subdir', 'DAGS_FOLDER/extract_load_dags.py', '--cfg-path', '/tmp/tmp4sjoi630', '--error-file', '/tmp/tmp09vrywie']
[2022-03-21 21:52:51,542] {standard_task_runner.py:77} INFO - Job 46: Subtask external_task_sensor
[2022-03-21 21:52:51,656] {logging_mixin.py:109} INFO - Running <TaskInstance: BQ_dag.external_task_sensor scheduled__2012-01-01T00:00:00+00:00 [running]> on host 7fae4c5ec6da
[2022-03-21 21:52:51,698] {taskinstance.py:1429} INFO - Exporting the following env vars:
AIRFLOW_CTX_DAG_OWNER=airflow
AIRFLOW_CTX_DAG_ID=BQ_dag
AIRFLOW_CTX_TASK_ID=external_task_sensor
AIRFLOW_CTX_EXECUTION_DATE=2012-01-01T00:00:00+00:00
AIRFLOW_CTX_DAG_RUN_ID=scheduled__2012-01-01T00:00:00+00:00
[2022-03-21 21:52:51,698] {external_task.py:169} INFO - Poking for tasks None in dag EL_dag on 2012-01-01T00:00:00+00:00 ... 
[2022-03-21 21:53:51,767] {external_task.py:169} INFO - Poking for tasks None in dag EL_dag on 2012-01-01T00:00:00+00:00 ... 
[2022-03-21 21:54:51,837] {external_task.py:169} INFO - Poking for tasks None in dag EL_dag on 2012-01-01T00:00:00+00:00 ... 
[2022-03-21 21:55:51,903] {external_task.py:169} INFO - Poking for tasks None in dag EL_dag on 2012-01-01T00:00:00+00:00 ... 
[2022-03-21 21:55:51,918] {taskinstance.py:1718} ERROR - Task failed with exception
Traceback (most recent call last):
  File "/usr/local/lib/python3.9/site-packages/airflow/models/taskinstance.py", line 1334, in _run_raw_task
    self._execute_task_with_callbacks(context)
  File "/usr/local/lib/python3.9/site-packages/airflow/models/taskinstance.py", line 1460, in _execute_task_with_callbacks
    result = self._execute_task(context, self.task)
  File "/usr/local/lib/python3.9/site-packages/airflow/models/taskinstance.py", line 1516, in _execute_task
    result = execute_callable(context=context)
  File "/usr/local/lib/python3.9/site-packages/airflow/sensors/base.py", line 242, in execute
    raise AirflowSensorTimeout(f"Snap. Time is OUT. DAG id: {log_dag_id}")
airflow.exceptions.AirflowSensorTimeout: Snap. Time is OUT. DAG id: BQ_dag
[2022-03-21 21:55:51,938] {taskinstance.py:1272} INFO - Immediate failure requested. Marking task as FAILED. dag_id=BQ_dag, task_id=external_task_sensor, execution_date=20120101T000000, start_date=20220321T215251, end_date=20220321T215551
[2022-03-21 21:55:51,949] {standard_task_runner.py:89} ERROR - Failed to execute job 46 for task external_task_sensor
Traceback (most recent call last):
  File "/usr/local/lib/python3.9/site-packages/airflow/task/task_runner/standard_task_runner.py", line 85, in _start_by_fork
    args.func(args, dag=self.dag)
  File "/usr/local/lib/python3.9/site-packages/airflow/cli/cli_parser.py", line 48, in command
    return func(*args, **kwargs)
  File "/usr/local/lib/python3.9/site-packages/airflow/utils/cli.py", line 92, in wrapper
    return f(*args, **kwargs)
  File "/usr/local/lib/python3.9/site-packages/airflow/cli/commands/task_command.py", line 298, in task_run
    _run_task_by_selected_method(args, dag, ti)
  File "/usr/local/lib/python3.9/site-packages/airflow/cli/commands/task_command.py", line 107, in _run_task_by_selected_method
    _run_raw_task(args, ti)
  File "/usr/local/lib/python3.9/site-packages/airflow/cli/commands/task_command.py", line 180, in _run_raw_task
    ti._run_raw_task(
  File "/usr/local/lib/python3.9/site-packages/airflow/utils/session.py", line 70, in wrapper
    return func(*args, session=session, **kwargs)
  File "/usr/local/lib/python3.9/site-packages/airflow/models/taskinstance.py", line 1334, in _run_raw_task
    self._execute_task_with_callbacks(context)
  File "/usr/local/lib/python3.9/site-packages/airflow/models/taskinstance.py", line 1460, in _execute_task_with_callbacks
    result = self._execute_task(context, self.task)
  File "/usr/local/lib/python3.9/site-packages/airflow/models/taskinstance.py", line 1516, in _execute_task
    result = execute_callable(context=context)
  File "/usr/local/lib/python3.9/site-packages/airflow/sensors/base.py", line 242, in execute
    raise AirflowSensorTimeout(f"Snap. Time is OUT. DAG id: {log_dag_id}")
airflow.exceptions.AirflowSensorTimeout: Snap. Time is OUT. DAG id: BQ_dag
[2022-03-21 21:55:51,958] {local_task_job.py:154} INFO - Task exited with return code 1
[2022-03-21 21:55:51,989] {local_task_job.py:264} INFO - 0 downstream tasks scheduled from follow-on schedule check
[2022-03-21 22:38:14,603] {taskinstance.py:1037} INFO - Dependencies all met for <TaskInstance: BQ_dag.external_task_sensor scheduled__2012-01-01T00:00:00+00:00 [queued]>
[2022-03-21 22:38:14,610] {taskinstance.py:1037} INFO - Dependencies all met for <TaskInstance: BQ_dag.external_task_sensor scheduled__2012-01-01T00:00:00+00:00 [queued]>
[2022-03-21 22:38:14,610] {taskinstance.py:1243} INFO - 
--------------------------------------------------------------------------------
[2022-03-21 22:38:14,610] {taskinstance.py:1244} INFO - Starting attempt 2 of 4
[2022-03-21 22:38:14,611] {taskinstance.py:1245} INFO - 
--------------------------------------------------------------------------------
[2022-03-21 22:38:14,618] {taskinstance.py:1264} INFO - Executing <Task(ExternalTaskSensor): external_task_sensor> on 2012-01-01 00:00:00+00:00
[2022-03-21 22:38:14,622] {standard_task_runner.py:52} INFO - Started process 720 to run task
[2022-03-21 22:38:14,624] {standard_task_runner.py:76} INFO - Running: ['airflow', 'tasks', 'run', 'BQ_dag', 'external_task_sensor', 'scheduled__2012-01-01T00:00:00+00:00', '--job-id', '67', '--raw', '--subdir', 'DAGS_FOLDER/extract_load_dags.py', '--cfg-path', '/tmp/tmpriq00lcb', '--error-file', '/tmp/tmp150zf6k2']
[2022-03-21 22:38:14,625] {standard_task_runner.py:77} INFO - Job 67: Subtask external_task_sensor
[2022-03-21 22:38:14,734] {logging_mixin.py:109} INFO - Running <TaskInstance: BQ_dag.external_task_sensor scheduled__2012-01-01T00:00:00+00:00 [running]> on host 7fae4c5ec6da
[2022-03-21 22:38:14,771] {taskinstance.py:1429} INFO - Exporting the following env vars:
AIRFLOW_CTX_DAG_OWNER=airflow
AIRFLOW_CTX_DAG_ID=BQ_dag
AIRFLOW_CTX_TASK_ID=external_task_sensor
AIRFLOW_CTX_EXECUTION_DATE=2012-01-01T00:00:00+00:00
AIRFLOW_CTX_DAG_RUN_ID=scheduled__2012-01-01T00:00:00+00:00
[2022-03-21 22:38:14,772] {external_task.py:169} INFO - Poking for tasks ['remove_dataset_task'] in dag EL_dag on 2012-01-01T00:10:00+00:00 ... 
[2022-03-21 22:39:14,842] {external_task.py:169} INFO - Poking for tasks ['remove_dataset_task'] in dag EL_dag on 2012-01-01T00:10:00+00:00 ... 
[2022-03-21 22:40:14,915] {external_task.py:169} INFO - Poking for tasks ['remove_dataset_task'] in dag EL_dag on 2012-01-01T00:10:00+00:00 ... 
[2022-03-21 22:40:20,971] {local_task_job.py:211} WARNING - State of this instance has been externally set to restarting. Terminating instance.
[2022-03-21 22:40:20,972] {process_utils.py:120} INFO - Sending Signals.SIGTERM to group 720. PIDs of all processes in the group: [720]
[2022-03-21 22:40:20,973] {process_utils.py:75} INFO - Sending the signal Signals.SIGTERM to group 720
[2022-03-21 22:40:20,973] {taskinstance.py:1413} ERROR - Received SIGTERM. Terminating subprocesses.
[2022-03-21 22:40:20,984] {taskinstance.py:1718} ERROR - Task failed with exception
Traceback (most recent call last):
  File "/usr/local/lib/python3.9/site-packages/airflow/models/taskinstance.py", line 1334, in _run_raw_task
    self._execute_task_with_callbacks(context)
  File "/usr/local/lib/python3.9/site-packages/airflow/models/taskinstance.py", line 1460, in _execute_task_with_callbacks
    result = self._execute_task(context, self.task)
  File "/usr/local/lib/python3.9/site-packages/airflow/models/taskinstance.py", line 1516, in _execute_task
    result = execute_callable(context=context)
  File "/usr/local/lib/python3.9/site-packages/airflow/sensors/base.py", line 249, in execute
    time.sleep(self._get_next_poke_interval(started_at, run_duration, try_number))
  File "/usr/local/lib/python3.9/site-packages/airflow/models/taskinstance.py", line 1415, in signal_handler
    raise AirflowException("Task received SIGTERM signal")
airflow.exceptions.AirflowException: Task received SIGTERM signal
[2022-03-21 22:40:20,988] {taskinstance.py:1272} INFO - Marking task as UP_FOR_RETRY. dag_id=BQ_dag, task_id=external_task_sensor, execution_date=20120101T000000, start_date=20220321T223814, end_date=20220321T224020
[2022-03-21 22:40:20,997] {standard_task_runner.py:89} ERROR - Failed to execute job 67 for task external_task_sensor
Traceback (most recent call last):
  File "/usr/local/lib/python3.9/site-packages/airflow/task/task_runner/standard_task_runner.py", line 85, in _start_by_fork
    args.func(args, dag=self.dag)
  File "/usr/local/lib/python3.9/site-packages/airflow/cli/cli_parser.py", line 48, in command
    return func(*args, **kwargs)
  File "/usr/local/lib/python3.9/site-packages/airflow/utils/cli.py", line 92, in wrapper
    return f(*args, **kwargs)
  File "/usr/local/lib/python3.9/site-packages/airflow/cli/commands/task_command.py", line 298, in task_run
    _run_task_by_selected_method(args, dag, ti)
  File "/usr/local/lib/python3.9/site-packages/airflow/cli/commands/task_command.py", line 107, in _run_task_by_selected_method
    _run_raw_task(args, ti)
  File "/usr/local/lib/python3.9/site-packages/airflow/cli/commands/task_command.py", line 180, in _run_raw_task
    ti._run_raw_task(
  File "/usr/local/lib/python3.9/site-packages/airflow/utils/session.py", line 70, in wrapper
    return func(*args, session=session, **kwargs)
  File "/usr/local/lib/python3.9/site-packages/airflow/models/taskinstance.py", line 1334, in _run_raw_task
    self._execute_task_with_callbacks(context)
  File "/usr/local/lib/python3.9/site-packages/airflow/models/taskinstance.py", line 1460, in _execute_task_with_callbacks
    result = self._execute_task(context, self.task)
  File "/usr/local/lib/python3.9/site-packages/airflow/models/taskinstance.py", line 1516, in _execute_task
    result = execute_callable(context=context)
  File "/usr/local/lib/python3.9/site-packages/airflow/sensors/base.py", line 249, in execute
    time.sleep(self._get_next_poke_interval(started_at, run_duration, try_number))
  File "/usr/local/lib/python3.9/site-packages/airflow/models/taskinstance.py", line 1415, in signal_handler
    raise AirflowException("Task received SIGTERM signal")
airflow.exceptions.AirflowException: Task received SIGTERM signal
[2022-03-21 22:40:21,025] {process_utils.py:70} INFO - Process psutil.Process(pid=720, status='terminated', exitcode=1, started='22:38:13') (720) terminated with exit code 1
